Workbook

Sheet NMG
A1: StartDate | B1: EndDate | C1: Status | D1: IPAddress | E1: Progress | F1: Duration (in seconds) | G1: Finished | H1: RecordedDate | I1: ResponseId | J1: RecipientLastName | K1: RecipientFirstName | L1: RecipientEmail | M1: ExternalReference | N1: LocationLatitude | O1: LocationLongitude | P1: DistributionChannel | Q1: UserLanguage | R1: Q1 | S1: Q2 | T1: Q3 | U1: Q4 | V1: Q4_5_TEXT | W1: Q5 | X1: Q5_4_TEXT | Y1: Q6 | Z1: Q7 | AA1: Q8 | AB1: Q9 | AC1: Q10 | AD1: Q11 | AE1: Q12 | AF1: Q13_1 | AG1: Q13_2 | AH1: Q13_3 | AI1: Q14_0 | AJ1: Q14 | AK1: Q15 | AL1: Q16 | AM1: Q16_1_TEXT | AN1: Q17 | AO1: Q18 | AP1: Q19 | AQ1: Q19_4_TEXT | AR1: Q20 | AS1: Q21_1 | AT1: Q21_2 | AU1: Q21_3 | AV1: Q21_4 | AW1: Q21_5 | AX1: Q21_6 | AY1: Q21_7 | AZ1: Q21_8 | BA1: Q21_9 | BB1: Q21_10 | BC1: Q21_11 | BD1: Q21_12 | BE1: Q21_13 | BF1: Q21_14 | BG1: Q21_15 | BH1: Q22_1 | BI1: Q22_2 | BJ1: Q22_3 | BK1: Q22_4 | BL1: Q22_5 | BM1: Q22_6 | BN1: Q22_7 | BO1: Q22_8 | BP1: Q22_9 | BQ1: Q22_10 | BR1: Q22_11 | BS1: Q23 | BT1: Q24_1 | BU1: Q24_2 | BV1: Q25_1 | BW1: Q25_2 | BX1: Q25_3 | BY1: Q25_4 | BZ1: Q25_5 | CA1: Q25_6 | CB1: Q25_7 | CC1: Q25_8 | CD1: Q25_9 | CE1: Q26 | CF1: Q27 | CG1: Q28 | CH1: Q29 | CI1: Q30 | CJ1: Q31 | CK1: Q32 | CL1: Q33 | CM1: Q34_1 | CN1: Q34_2 | CO1: Q34_3 | CP1: Q34_4 | CQ1: Q35 | CR1: Q35_5_TEXT | CS1: Q36 | CT1: Q37 | CU1: Q38 | CV1: Q39 | CW1: Q39_5_TEXT | CX1: Q40 | CY1: Q41 | CZ1: Q42 | DA1: Q42_8_TEXT | DB1: Q43 | DC1: Q44 | DD1: Q45 | DE1: PROLIFIC_PID | DF1: Indicators_Satisfied
A2: 45718.427 | B2: 45718.431 | C2: 0 | D2: 67.81.6.206 | E2: 100 | F2: 354 | G2: 1 | H2: 45718.431 | I2: R_7CkbrcvxqUIp5ex | N2: 40.8534 | O2: -73.4115 | P2: anonymous | Q2: EN | R2: 1 | S2: 611037a84b048a5bed5c3c96 | T2: 2 | U2: 1 | W2: 2 | Y2: 7 | Z2: 1 | AA2: 1 | AB2: 2 | AC2: 3 | AD2: 5 | AE2: 1 | AF2: 2 | AG2: 2 | AH2: 2 | AI2: 1 | AJ2: 2 | AK2: 1 | AL2: 2 | AN2: 4 | AO2: 2 | AP2: 4 | AQ2: install pumps | AR2: 1 | AS2: 4 | AT2: 4 | AU2: 3 | AV2: 3 | AW2: 3 | AX2: 2 | AY2: 2 | AZ2: 1 | BA2: 3 | BB2: 3 | BC2: 3 | BD2: 1 | BE2: 3 | BF2: 4 | BG2: 3 | BH2: 4 | BI2: 4 | BJ2: 4 | BK2: 4 | BL2: 2 | BM2: 4 | BN2: 2 | BO2: 2 | BP2: 4 | BQ2: 4 | BR2: 3 | BS2: 3 | BT2: 2 | BU2: 2 | BV2: 3 | BW2: 3 | BX2: 2 | BY2: 3 | BZ2: 3 | CA2: 3 | CB2: 3 | CC2: 3 | CD2: 3 | CE2: 4 | CF2: 2 | CG2: 2 | CH2: 1 | CI2: 1 | CJ2: 1 | CK2: 3 | CM2: 2 | CN2: 3 | CO2: 4 | CP2: 1 | CQ2: 1 | CS2: 1 | CT2: 3 | CU2: 4 | CV2: 2 | CX2: 1 | CY2: 1 | CZ2: 3 | DB2: 10 | DC2: 11743 | DE2: 611037a84b048a5bed5c3c96 | DF2: 0
A3: 45718.43 | B3: 45718.437 | C3: 0 | D3: 24.44.50.98 | E3: 100 | F3: 593 | G3: 1 | H3: 45718.437 | I3: R_5r248g6QqsZYeYk | N3: 40.608 | O3: -74.5265 | P3: anonymous | Q3: EN | R3: 1 | S3: 65fc7aec8851ded695c2fd8a | T3: 1 | U3: 2 | W3: 2 | Y3: 1 | Z3: 1 | AA3: 1 | AB3: 2 | AC3: 1 | AD3: 2 | AE3: 1 | AF3: 2 | AG3: 2 | AH3: 2 | AI3: 2 | AJ3: 1 | AS3: 4 | AT3: 4 | AU3: 3 | AV3: 3 | AW3: 3 | AX3: 4 | AY3: 3 | AZ3: 2 | BA3: 3 | BB3: 2 | BC3: 2 | BD3: 3 | BE3: 3 | BF3: 4 | BG3: 3 | BH3: 3 | BI3: 4 | BJ3: 3 | BK3: 4 | BL3: 5 | BM3: 2 | BN3: 2 | BO3: 4 | BP3: 4 | BQ3: 4 | BR3: 2 | BS3: 3 | BT3: 2 | BU3: 2 | BV3: 3 | BW3: 3 | BX3: 2 | BY3: 4 | BZ3: 3 | CA3: 3 | CB3: 5 | CC3: 2 | CD3: 3 | CE3: 1 | CF3: 5 | CG3: 1 | CH3: 2 | CI3: 1 | CJ3: 2 | CK3: 2 | CM3: 1 | CN3: 3 | CO3: 2 | CP3: 4 | CQ3: 2 | CS3: 2 | CT3: 3 | CU3: 4 | CV3: 1 | CX3: 1 | CY3: 1 | CZ3: 8 | DA3: Technical Support | DB3: 10 | DC3: 08869 | DE3: 65fc7aec8851ded695c2fd8a | DF3: 0
A4: 45718.426 | B4: 45718.437 | C4: 0 | D4: 172.59.208.237 | E4: 100 | F4: 942 | G4: 1 | H4: 45718.437 | I4: R_7CiUYRtayo3pZFH | N4: 40.7463 | O4: -74.1553 | P4: anonymous | Q4: EN | R4: 1 | S4: 67c0c4f757d625c937fa4cf9 | T4: 1 | U4: 1 | W4: 3 | Y4: 5 | Z4: 1 | AA4: 1 | AB4: 1 | AC4: 3 | AD4: 2 | AE4: 1 | AF4: 1 | AG4: 2 | AH4: 2 | AI4: 1 | AJ4: 2 | AK4: 2 | AL4: 1 | AN4: 2 | AO4: 1 | AP4: 3 | AR4: 1 | AS4: 3 | AT4: 3 | AU4: 4 | AV4: 4 | AW4: 2 | AX4: 2 | AY4: 3 | AZ4: 4 | BA4: 4 | BB4: 4 | BC4: 4 | BD4: 5 | BE4: 4 | BF4: 4 | BG4: 2 | BH4: 4 | BI4: 3 | BJ4: 5 | BK4: 4 | BL4: 4 | BM4: 5 | BN4: 4 | BO4: 4 | BP4: 2 | BQ4: 4 | BR4: 4 | BS4: 3 | BT4: 4 | BU4: 5 | BV4: 4 | BW4: 4 | BX4: 5 | BY4: 5 | BZ4: 5 | CA4: 5 | CB4: 5 | CC4: 4 | CD4: 5 | CE4: 2 | CF4: 5 | CG4: 4 | CH4: 4 | CI4: 4 | CJ4: 4 | CK4: 2 | CM4: 3 | CN4: 1 | CO4: 2 | CP4: 4 | CQ4: 2 | CS4: 1 | CT4: 3 | CU4: 2 | CV4: 1 | CX4: 1 | CY4: 2 | CZ4: 8 | DB4: 10 | DC4: 07206 | DE4: 67c0c4f757d625c937fa4cf9 | DF4: 0
A5: 45718.432 | B5: 45718.438 | C5: 0 | D5: 74.102.159.69 | E5: 100 | F5: 569 | G5: 1 | H5: 45718.438 | I5: R_7QryMPJ8k5wNCWm | N5: 40.7463 | O5: -74.1553 | P5: anonymous | Q5: EN | R5: 1 | S5: 65635241f6b4756ac64c57eb | T5: 1 | U5: 1 | W5: 2 | Y5: 1 | Z5: 1 | AA5: 1 | AB5: 2 | AC5: 2 | AD5: 3 | AE5: 1 | AF5: 2 | AG5: 2 | AH5: 2 | AI5: 2 | AJ5: 1 | AS5: 5 | AT5: 5 | AU5: 5 | AV5: 4 | AW5: 4 | AX5: 4 | AY5: 3 | AZ5: 3 | BA5: 4 | BB5: 3 | BC5: 4 | BD5: 4 | BE5: 4 | BF5: 4 | BG5: 4 | BH5: 5 | BI5: 1 | BJ5: 2 | BK5: 2 | BL5: 2 | BM5: 2 | BN5: 2 | BO5: 1 | BP5: 1 | BQ5: 1 | BR5: 1 | BS5: 3 | BT5: 2 | BU5: 2 | BV5: 2 | BW5: 2 | BX5: 4 | BY5: 4 | BZ5: 4 | CA5: 4 | CB5: 5 | CC5: 4 | CD5: 4 | CE5: 1 | CF5: 2 | CG5: 1 | CH5: 4 | CI5: 2 | CJ5: 4 | CK5: 2 | CM5: 2 | CN5: 1 | CO5: 3 | CP5: 4 | CQ5: 2 | CS5: 1 | CT5: 3 | CU5: 1 | CV5: 1 | CX5: 1 | CY5: 1 | CZ5: 4 | DB5: 10 | DC5: 07604 | DE5: 65635241f6b4756ac64c57eb | DF5: 0
A6: 45718.433 | B6: 45718.441 | C6: 0 | D6: 140.174.71.233 | E6: 100 | F6: 612 | G6: 1 | H6: 45718.441 | I6: R_1NKghBSgfSUuAE4 | N6: 41.0534 | O6: -73.5387 | P6: anonymous | Q6: EN | R6: 1 | S6: 654fe6af3517f92a06444ca5 | T6: 2 | U6: 3 | W6: 1 | Y6: 6 | Z6: 2 | AA6: 1 | AB6: 2 | AC6: 2 | AD6: 2 | AE6: 1 | AF6: 2 | AG6: 2 | AH6: 2 | AI6: 2 | AJ6: 1 | AS6: 2 | AT6: 3 | AU6: 3 | AV6: 2 | AW6: 3 | AX6: 3 | AY6: 3 | AZ6: 3 | BA6: 3 | BB6: 2 | BC6: 3 | BD6: 3 | BE6: 3 | BF6: 2 | BG6: 2 | BH6: 4 | BI6: 4 | BJ6: 2 | BK6: 2 | BL6: 2 | BM6: 2 | BN6: 2 | BO6: 4 | BP6: 4 | BQ6: 4 | BR6: 3 | BS6: 3 | BT6: 1 | BU6: 1 | BV6: 4 | BW6: 4 | BX6: 2 | BY6: 3 | BZ6: 2 | CA6: 2 | CB6: 3 | CC6: 2 | CD6: 2 | CE6: 1 | CF6: 4 | CG6: 1 | CL6: 4 | CQ6: 2 | CS6: 2 | CT6: 3 | CU6: 1 | CV6: 1 | CX6: 1 | CY6: 2 | CZ6: 4 | DB6: 10 | DC6: 10016 | DE6: 654fe6af3517f92a06444ca5 | DF6: 0
A7: 45718.436 | B7: 45718.441 | C7: 0 | D7: 68.192.75.150 | E7: 100 | F7: 484 | G7: 1 | H7: 45718.441 | I7: R_5sV6WsT12XDr7pL | N7: 41.1484 | O7: -74.5827 | P7: anonymous | Q7: EN | R7: 1 | S7: 5f6e04d24dfd8f2c88366a29 | T7: 1 | U7: 2 | W7: 1 | Y7: 1 | Z7: 2 | AA7: 1 | AB7: 2 | AC7: 2 | AD7: 2 | AE7: 1 | AF7: 2 | AG7: 2 | AH7: 2 | AI7: 2 | AJ7: 1 | AS7: 3 | AT7: 3 | AU7: 3 | AV7: 2 | AW7: 4 | AX7: 3 | AY7: 1 | AZ7: 1 | BA7: 1 | BB7: 1 | BC7: 2 | BD7: 1 | BE7: 1 | BF7: 4 | BG7: 1 | BH7: 1 | BI7: 1 | BJ7: 1 | BK7: 1 | BL7: 3 | BM7: 1 | BN7: 1 | BO7: 3 | BP7: 1 | BQ7: 1 | BR7: 1 | BS7: 3 | BT7: 1 | BU7: 2 | BV7: 2 | BW7: 3 | BX7: 1 | BY7: 4 | BZ7: 4 | CA7: 2 | CB7: 3 | CC7: 1 | CD7: 2 | CE7: 4 | CF7: 1 | CG7: 1 | CL7: 1 | CQ7: 3 | CS7: 1 | CT7: 2 | CU7: 4 | CV7: 2 | CX7: 1 | CY7: 1 | CZ7: 3 | DB7: 10 | DC7: 07416 | DE7: 5f6e04d24dfd8f2c88366a29 | DF7: 0
A8: 45718.427 | B8: 45718.442 | C8: 0 | D8: 69.122.18.136 | E8: 100 | F8: 1316 | G8: 1 | H8: 45718.442 | I8: R_6D76h8bDEQy3HyC | N8: 40.5175 | O8: -74.3991 | P8: anonymous | Q8: EN | R8: 1 | S8: 66a2fc3f7be0914ea068ea6a | T8: 1 | U8: 1 | W8: 1 | Y8: 7 | Z8: 1 | AA8: 1 | AB8: 1 | AC8: 3 | AD8: 3 | AE8: 1 | AF8: 2 | AG8: 2 | AH8: 2 | AI8: 2 | AJ8: 1 | AS8: 3 | AT8: 3 | AU8: 3 | AV8: 3 | AW8: 3 | AX8: 3 | AY8: 1 | AZ8: 1 | BA8: 3 | BB8: 1 | BC8: 3 | BD8: 2 | BE8: 3 | BF8: 3 | BG8: 3 | BH8: 4 | BI8: 2 | BJ8: 2 | BK8: 2 | BL8: 4 | BM8: 2 | BN8: 4 | BO8: 2 | BP8: 3 | BQ8: 2 | BR8: 2 | BS8: 3 | BT8: 2 | BU8: 2 | BV8: 4 | BW8: 3 | BX8: 2 | BY8: 4 | BZ8: 3 | CA8: 2 | CB8: 4 | CC8: 3 | CD8: 2 | CE8: 1 | CF8: 2 | CG8: 1 | CL8: 3 | CQ8: 2 | CS8: 1 | CT8: 2 | CU8: 3 | CV8: 2 | CX8: 1 | CY8: 2 | CZ8: 6 | DB8: 6 | DC8: 08854 | DE8: 66a2fc3f7be0914ea068ea6a | DF8: 0
A9: 45718.434 | B9: 45718.443 | C9: 0 | D9: 108.5.179.42 | E9: 100 | F9: 719 | G9: 1 | H9: 45718.443 | I9: R_3iepfnPlDsSzVqg | N9: 40.6342 | O9: -74.2427 | P9: anonymous | Q9: EN | R9: 1 | S9: 5e1a3bc7477f3b2ba490bde1 | T9: 1 | U9: 2 | W9: 1 | Y9: 6 | Z9: 2 | AA9: 1 | AB9: 2 | AC9: 1 | AD9: 2 | AE9: 1 | AF9: 2 | AG9: 2 | AH9: 2 | AI9: 2 | AJ9: 1 | AS9: 4 | AT9: 4 | AU9: 4 | AV9: 4 | AW9: 3 | AX9: 3 | AY9: 3 | AZ9: 2 | BA9: 3 | BB9: 5 | BC9: 4 | BD9: 2 | BE9: 2 | BF9: 5 | BG9: 5 | BH9: 1 | BI9: 1 | BJ9: 2 | BK9: 4 | BL9: 4 | BM9: 4 | BN9: 2 | BO9: 1 | BP9: 1 | BQ9: 3 | BR9: 1 | BS9: 3 | BT9: 3 | BU9: 4 | BV9: 4 | BW9: 2 | BX9: 5 | BY9: 5 | BZ9: 1 | CA9: 4 | CB9: 4 | CC9: 1 | CD9: 4 | CE9: 4 | CF9: 2 | CG9: 1 | CL9: 3 | CQ9: 1 | CS9: 2 | CT9: 4 | CU9: 4 | CV9: 1 | CX9: 1 | CY9: 1 | CZ9: 3 | DB9: 8 | DC9: 07203 | DD9: Some of the questions I might have had different answers for if they were phrased slightly differently. For instance, my larger community, like the town I live in, floods all the time, but my immediate community, the apartment complex I live in, is higher in elevation and never floods, even when everyone around us does. I answered questions based on defining community as my apartment community, but I'm not sure if all would have interpreted the questions like that. | DE9: 5e1a3bc7477f3b2ba490bde1 | DF9: 0
A10: 45718.44 | B10: 45718.444 | C10: 0 | D10: 74.90.37.4 | E10: 100 | F10: 297 | G10: 1 | H10: 45718.444 | I10: R_3EaW5xxnTIE5h8t | N10: 40.9451 | O10: -74.2531 | P10: anonymous | Q10: EN | R10: 1 | S10: 66d06fd15b37d17345069c4c | T10: 1 | U10: 1 | W10: 2 | Y10: 1 | Z10: 2 | AA10: 1 | AB10: 2 | AC10: 4 | AD10: 4 | AE10: 1 | AF10: 2 | AG10: 1 | AH10: 2 | AI10: 2 | AJ10: 1 | AS10: 5 | AT10: 4 | AU10: 4 | AV10: 4 | AW10: 4 | AX10: 4 | AY10: 5 | AZ10: 4 | BA10: 4 | BB10: 5 | BC10: 5 | BD10: 3 | BE10: 5 | BF10: 4 | BG10: 3 | BH10: 1 | BI10: 1 | BJ10: 2 | BK10: 4 | BL10: 3 | BM10: 4 | BN10: 2 | BO10: 2 | BP10: 2 | BQ10: 2 | BR10: 1 | BS10: 3 | BT10: 4 | BU10: 4 | BV10: 2 | BW10: 2 | BX10: 2 | BY10: 4 | BZ10: 2 | CA10: 2 | CB10: 2 | CC10: 2 | CD10: 2 | CE10: 4 | CF10: 2 | CG10: 1 | CH10: 1 | CI10: 1 | CJ10: 1 | CK10: 1 | CM10: 2 | CN10: 3 | CO10: 4 | CP10: 1 | CQ10: 2 | CS10: 3 | CT10: 4 | CU10: 4 | CV10: 2 | CX10: 1 | CY10: 2 | CZ10: 4 | DB10: 10 | DC10: 07470 | DE10: 66d06fd15b37d17345069c4c | DF10: 0
A11: 45718.443 | B11: 45718.449 | C11: 0 | D11: 174.229.241.241 | E11: 100 | F11: 549 | G11: 1 | H11: 45718.449 | I11: R_5rTupkC4wUKF5Vg | N11: 40.9261 | O11: -74.1419 | P11: anonymous | Q11: EN | R11: 1 | S11: 653403fb4c4cee1065807251 | T11: 1 | U11: 3 | W11: 1 | Y11: 1 | Z11: 1 | AA11: 1 | AB11: 2 | AC11: 1 | AD11: 2 | AE11: 1 | AF11: 2 | AG11: 2 | AH11: 2 | AI11: 2 | AJ11: 1 | AS11: 3 | AT11: 3 | AU11: 4 | AV11: 3 | AW11: 3 | AX11: 3 | AY11: 3 | AZ11: 3 | BA11: 3 | BB11: 3 | BC11: 3 | BD11: 3 | BE11: 3 | BF11: 4 | BG11: 3 | BH11: 3 | BI11: 3 | BJ11: 2 | BK11: 3 | BL11: 3 | BM11: 2 | BN11: 2 | BO11: 3 | BP11: 3 | BQ11: 3 | BR11: 3 | BS11: 3 | BT11: 2 | BU11: 2 | BV11: 3 | BW11: 3 | BX11: 2 | BY11: 3 | BZ11: 3 | CA11: 2 | CB11: 3 | CC11: 3 | CD11: 2 | CE11: 4 | CF11: 4 | CG11: 1 | CL11: 3 | CQ11: 2 | CS11: 3 | CT11: 3 | CU11: 4 | CV11: 1 | CX11: 1 | CY11: 1 | CZ11: 4 | DB11: 9 | DC11: 07047 | DE11: 653403fb4c4cee1065807251 | DF11: 0
A12: 45718.445 | B12: 45718.449 | C12: 0 | D12: 73.198.91.94 | E12: 100 | F12: 329 | G12: 1 | H12: 45718.449 | I12: R_5zQQPdbSkYD8Pp7 | N12: 39.7513 | O12: -74.9999 | P12: anonymous | Q12: EN | R12: 1 | S12: 6647c117352b708167ccfd48 | T12: 1 | U12: 1 | W12: 2 | Y12: 4 | Z12: 2 | AA12: 1 | AB12: 2 | AC12: 4 | AD12: 4 | AE12: 1 | AF12: 2 | AG12: 2 | AH12: 2 | AI12: 2 | AJ12: 1 | AS12: 4 | AT12: 4 | AU12: 5 | AV12: 4 | AW12: 3 | AX12: 3 | AY12: 4 | AZ12: 5 | BA12: 5 | BB12: 4 | BC12: 3 | BD12: 3 | BE12: 4 | BF12: 3 | BG12: 3 | BH12: 4 | BI12: 3 | BJ12: 2 | BK12: 2 | BL12: 1 | BM12: 1 | BN12: 1 | BO12: 4 | BP12: 4 | BQ12: 3 | BR12: 2 | BS12: 3 | BT12: 1 | BU12: 1 | BV12: 3 | BW12: 2 | BX12: 3 | BY12: 4 | BZ12: 4 | CA12: 3 | CB12: 4 | CC12: 2 | CD12: 3 | CE12: 4 | CF12: 4 | CG12: 1 | CH12: 3 | CI12: 2 | CJ12: 3 | CK12: 4 | CM12: 1 | CN12: 2 | CO12: 3 | CP12: 4 | CQ12: 1 | CS12: 4 | CT12: 3 | CU12: 4 | CV12: 1 | CX12: 1 | CY12: 2 | CZ12: 3 | DB12: 10 | DC12: 08051 | DE12: 6647c117352b708167ccfd48 | DF12: 0
A13: 45718.436 | B13: 45718.449 | C13: 0 | D13: 131.125.11.1 | E13: 100 | F13: 1149 | G13: 1 | H13: 45718.449 | I13: R_1h6j419H5CulNWM | N13: 40.6947 | O13: -74.2688 | P13: anonymous | Q13: EN | R13: 1 | S13: 6789c5aa3a931b6efcc2ea61 | T13: 1 | U13: 2 | W13: 2 | Y13: 4 | Z13: 1 | AA13: 1 | AB13: 2 | AC13: 5 | AD13: 3 | AE13: 1 | AF13: 2 | AG13: 1 | AH13: 2 | AI13: 1 | AJ13: 2 | AK13: 2 | AL13: 2 | AN13: 2 | AO13: 2 | AP13: 1 | AR13: 1 | AS13: 5 | AT13: 5 | AU13: 5 | AV13: 5 | AW13: 5 | AX13: 2 | AY13: 5 | AZ13: 5 | BA13: 5 | BB13: 5 | BC13: 4 | BD13: 5 | BE13: 5 | BF13: 5 | BG13: 5 | BH13: 4 | BI13: 4 | BJ13: 3 | BK13: 5 | BL13: 5 | BM13: 5 | BN13: 4 | BO13: 4 | BP13: 3 | BQ13: 4 | BR13: 4 | BS13: 3 | BT13: 5 | BU13: 5 | BV13: 4 | BW13: 3 | BX13: 5 | BY13: 4 | BZ13: 5 | CA13: 4 | CB13: 2 | CC13: 3 | CD13: 3 | CE13: 2 | CF13: 3 | CG13: 1 | CH13: 4 | CI13: 2 | CJ13: 2 | CK13: 1 | CM13: 1 | CN13: 2 | CO13: 3 | CP13: 4 | CQ13: 2 | CS13: 1 | CT13: 2 | CU13: 4 | CV13: 1 | CX13: 1 | CY13: 2 | CZ13: 4 | DB13: 7 | DC13: 08831 | DE13: 6789c5aa3a931b6efcc2ea61 | DF13: 0
A14: 45718.443 | B14: 45718.449 | C14: 0 | D14: 69.125.203.57 | E14: 100 | F14: 593 | G14: 1 | H14: 45718.449 | I14: R_5o1xo7wN5E9KMox | N14: 40.2066 | O14: -74.0727 | P14: anonymous | Q14: EN | R14: 1 | S14: 594d4f0aa186be000114ce1d | T14: 1 | U14: 1 | W14: 2 | Y14: 3 | Z14: 1 | AA14: 1 | AB14: 2 | AC14: 3 | AD14: 2 | AE14: 1 | AF14: 1 | AG14: 2 | AH14: 2 | AI14: 2 | AJ14: 1 | AS14: 4 | AT14: 4 | AU14: 4 | AV14: 4 | AW14: 2 | AX14: 2 | AY14: 3 | AZ14: 4 | BA14: 3 | BB14: 3 | BC14: 2 | BD14: 2 | BE14: 3 | BF14: 4 | BG14: 2 | BH14: 2 | BI14: 2 | BJ14: 2 | BK14: 3 | BL14: 4 | BM14: 3 | BN14: 4 | BO14: 2 | BP14: 2 | BQ14: 2 | BR14: 1 | BS14: 3 | BT14: 2 | BU14: 3 | BV14: 2 | BW14: 2 | BX14: 2 | BY14: 4 | BZ14: 2 | CA14: 2 | CB14: 5 | CC14: 3 | CD14: 3 | CE14: 1 | CF14: 2 | CG14: 1 | CH14: 1 | CI14: 1 | CJ14: 1 | CK14: 3 | CM14: 1 | CN14: 3 | CO14: 4 | CP14: 2 | CQ14: 2 | CS14: 1 | CT14: 3 | CU14: 3 | CV14: 1 | CX14: 1 | CY14: 1 | CZ14: 3 | DB14: 10 | DC14: 07719 | DE14: 594d4f0aa186be000114ce1d | DF14: 0
A15: 45718.444 | B15: 45718.449 | C15: 0 | D15: 71.58.35.0 | E15: 100 | F15: 435 | G15: 1 | H15: 45718.449 | I15: R_7d6UYadE8f2Ca3J | N15: 39.9733 | O15: -74.248 | P15: anonymous | Q15: EN | R15: 1 | S15: 67a4fb352efb6fe83eb694c7 | T15: 1 | U15: 1 | W15: 1 | Y15: 2 | Z15: 2 | AA15: 1 | AB15: 2 | AC15: 1 | AD15: 2 | AE15: 1 | AF15: 2 | AG15: 2 | AH15: 1 | AI15: 2 | AJ15: 1 | AS15: 4 | AT15: 4 | AU15: 4 | AV15: 4 | AW15: 4 | AX15: 4 | AY15: 3 | AZ15: 3 | BA15: 3 | BB15: 4 | BC15: 3 | BD15: 2 | BE15: 3 | BF15: 4 | BG15: 3 | BH15: 2 | BI15: 2 | BJ15: 2 | BK15: 4 | BL15: 4 | BM15: 4 | BN15: 4 | BO15: 4 | BP15: 4 | BQ15: 2 | BR15: 2 | BS15: 3 | BT15: 4 | BU15: 4 | BV15: 4 | BW15: 2 | BX15: 3 | BY15: 4 | BZ15: 3 | CA15: 3 | CB15: 4 | CC15: 3 | CD15: 4 | CE15: 4 | CF15: 1 | CG15: 2 | CL15: 2 | CQ15: 2 | CS15: 6 | CT15: 3 | CU15: 4 | CV15: 4 | CX15: 1 | CY15: 1 | CZ15: 8 | DB15: 2 | DC15: 08757 | DE15: 67a4fb352efb6fe83eb694c7 | DF15: 0
A16: 45718.443 | B16: 45718.451 | C16: 0 | D16: 96.250.56.141 | E16: 100 | F16: 742 | G16: 1 | H16: 45718.451 | I16: R_1ZWxUgOMe8mCpuV | N16: 41.0155 | O16: -73.8635 | P16: anonymous | Q16: EN | R16: 1 | S16: 67aa8ca32e7acec145f34f7a | T16: 2 | U16: 1 | W16: 1 | Y16: 1 | Z16: 2 | AA16: 1 | AB16: 2 | AC16: 6 | AD16: 7 | AE16: 2 | AF16: 1 | AG16: 1 | AH16: 1 | AI16: 2 | AJ16: 1 | AS16: 4 | AT16: 4 | AU16: 5 | AV16: 5 | AW16: 4 | AX16: 4 | AY16: 4 | AZ16: 4 | BA16: 4 | BB16: 4 | BC16: 4 | BD16: 3 | BE16: 4 | BF16: 4 | BG16: 4 | BH16: 2 | BI16: 2 | BJ16: 4 | BK16: 4 | BL16: 2 | BM16: 4 | BN16: 2 | BO16: 4 | BP16: 4 | BQ16: 4 | BR16: 2 | BS16: 3 | BT16: 4 | BU16: 4 | BV16: 2 | BW16: 2 | BX16: 2 | BY16: 2 | BZ16: 2 | CA16: 2 | CB16: 2 | CC16: 2 | CD16: 2 | CE16: 4 | CF16: 2 | CG16: 2 | CL16: 2 | CQ16: 1 | CS16: 3 | CT16: 4 | CU16: 1 | CV16: 1 | CX16: 1 | CY16: 1 | CZ16: 3 | DB16: 10 | DC16: 10533 | DE16: 67aa8ca32e7acec145f34f7a | DF16: 0
A17: 45718.449 | B17: 45718.451 | C17: 0 | D17: 174.193.17.253 | E17: 100 | F17: 181 | G17: 1 | H17: 45718.451 | I17: R_53r0zR46p8tkHDK | N17: 40.7643 | O17: -74.148 | P17: anonymous | Q17: EN | R17: 1 | S17: 5d1e4f1d51bab90018162332 | T17: 1 | U17: 2 | W17: 1 | Y17: 3 | Z17: 1 | AA17: 1 | AB17: 2 | AC17: 2 | AD17: 2 | AE17: 1 | AF17: 2 | AG17: 2 | AH17: 2 | AI17: 1 | AJ17: 2 | AK17: 2 | AL17: 2 | AN17: 2 | AO17: 2 | AP17: 5 | AR17: 1 | AS17: 4 | AT17: 4 | AU17: 4 | AV17: 4 | AW17: 3 | AX17: 3 | AY17: 2 | AZ17: 3 | BA17: 3 | BB17: 3 | BC17: 3 | BD17: 4 | BE17: 4 | BF17: 4 | BG17: 3 | BH17: 4 | BI17: 4 | BJ17: 2 | BK17: 4 | BL17: 4 | BM17: 4 | BN17: 3 | BO17: 3 | BP17: 4 | BQ17: 4 | BR17: 3 | BS17: 3 | BT17: 4 | BU17: 4 | BV17: 4 | BW17: 4 | BX17: 4 | BY17: 4 | BZ17: 4 | CA17: 3 | CB17: 3 | CC17: 4 | CD17: 4 | CE17: 1 | CF17: 3 | CG17: 2 | CL17: 4 | CQ17: 1 | CS17: 2 | CT17: 3 | CU17: 4 | CV17: 1 | CX17: 1 | CY17: 1 | CZ17: 3 | DB17: 10 | DC17: 07644 | DE17: 5d1e4f1d51bab90018162332 | DF17: 0
A18: 45718.445 | B18: 45718.452 | C18: 0 | D18: 174.228.168.94 | E18: 100 | F18: 573 | G18: 1 | H18: 45718.452 | I18: R_5Pvqp2y5OE8crYY | N18: 28.4883 | O18: -81.4061 | P18: anonymous | Q18: EN | R18: 1 | S18: 673801f035173a7a962e8a7b | T18: 2 | U18: 1 | W18: 3 | Y18: 1 | Z18: 1 | AA18: 1 | AB18: 2 | AC18: 1 | AD18: 6 | AE18: 2 | AF18: 2 | AG18: 2 | AH18: 1 | AI18: 2 | AJ18: 1 | AS18: 4 | AT18: 4 | AU18: 4 | AV18: 4 | AW18: 3 | AX18: 3 | AY18: 4 | AZ18: 4 | BA18: 4 | BB18: 4 | BC18: 3 | BD18: 3 | BE18: 3 | BF18: 2 | BG18: 3 | BH18: 4 | BI18: 1 | BJ18: 3 | BK18: 3 | BL18: 4 | BM18: 4 | BN18: 4 | BO18: 3 | BP18: 2 | BQ18: 2 | BR18: 3 | BS18: 3 | BT18: 4 | BU18: 3 | BV18: 3 | BW18: 3 | BX18: 4 | BY18: 3 | BZ18: 2 | CA18: 3 | CB18: 3 | CC18: 3 | CD18: 3 | CE18: 4 | CF18: 2 | CG18: 1 | CH18: 3 | CI18: 1 | CJ18: 3 | CK18: 4 | CM18: 1 | CN18: 2 | CO18: 3 | CP18: 4 | CQ18: 1 | CS18: 6 | CT18: 2 | CU18: 4 | CV18: 4 | CX18: 1 | CY18: 2 | CZ18: 8 | DB18: 2 | DC18: 13905 | DE18: 673801f035173a7a962e8a7b | DF18: 0
A19: 45718.447 | B19: 45718.452 | C19: 0 | D19: 206.171.36.86 | E19: 100 | F19: 475 | G19: 1 | H19: 45718.452 | I19: R_6wzqVxZvgKxsGaQ | N19: 40.7785 | O19: -73.9898 | P19: anonymous | Q19: EN | R19: 1 | S19: 66844b7e12b7e64a89b7161e | T19: 2 | U19: 3 | W19: 2 | Y19: 1 | Z19: 1 | AA19: 1 | AB19: 2 | AC19: 3 | AD19: 3 | AE19: 2 | AF19: 1 | AG19: 2 | AH19: 2 | AI19: 2 | AJ19: 1 | AS19: 4 | AT19: 4 | AU19: 4 | AV19: 4 | AW19: 3 | AX19: 3 | AY19: 3 | AZ19: 2 | BA19: 4 | BB19: 4 | BC19: 3 | BD19: 4 | BE19: 3 | BF19: 5 | BG19: 4 | BH19: 5 | BI19: 3 | BJ19: 5 | BK19: 4 | BL19: 4 | BM19: 4 | BN19: 4 | BO19: 3 | BP19: 5 | BQ19: 4 | BR19: 4 | BS19: 3 | BT19: 3 | BU19: 3 | BV19: 3 | BW19: 2 | BX19: 3 | BY19: 3 | BZ19: 2 | CA19: 2 | CB19: 1 | CC19: 1 | CD19: 2 | CE19: 2 | CF19: 1 | CG19: 1 | CH19: 1 | CI19: 1 | CJ19: 2 | CK19: 4 | CM19: 2 | CN19: 4 | CO19: 3 | CP19: 1 | CQ19: 1 | CS19: 2 | CT19: 4 | CU19: 4 | CV19: 1 | CX19: 1 | CY19: 1 | CZ19: 3 | DB19: 10 | DC19: 10065 | DE19: 66844b7e12b7e64a89b7161e | DF19: 0
A20: 45718.445 | B20: 45718.452 | C20: 0 | D20: 69.122.17.118 | E20: 100 | F20: 680 | G20: 1 | H20: 45718.452 | I20: R_5EhysVaDFYIVjUQ | N20: 40.5175 | O20: -74.3991 | P20: anonymous | Q20: EN | R20: 1 | S20: 5f32e130f2bc3308c42ca980 | T20: 1 | U20: 2 | W20: 1 | Y20: 1 | Z20: 2 | AA20: 1 | AB20: 2 | AC20: 2 | AD20: 5 | AE20: 1 | AF20: 2 | AG20: 2 | AH20: 2 | AI20: 2 | AJ20: 1 | AS20: 3 | AT20: 3 | AU20: 4 | AV20: 3 | AW20: 3 | AX20: 4 | AY20: 1 | AZ20: 3 | BA20: 2 | BB20: 2 | BC20: 2 | BD20: 1 | BE20: 2 | BF20: 1 | BG20: 1 | BH20: 4 | BI20: 2 | BJ20: 1 | BK20: 4 | BL20: 2 | BM20: 2 | BN20: 2 | BO20: 1 | BP20: 4 | BQ20: 2 | BR20: 2 | BS20: 3 | BT20: 1 | BU20: 2 | BV20: 4 | BW20: 3 | BX20: 2 | BY20: 2 | BZ20: 2 | CA20: 4 | CB20: 4 | CC20: 2 | CD20: 4 | CE20: 4 | CF20: 4 | CG20: 2 | CL20: 4 | CQ20: 1 | CS20: 1 | CT20: 2 | CU20: 4 | CV20: 2 | CX20: 1 | CY20: 1 | CZ20: 3 | DB20: 9 | DC20: 08812 | DE20: 5f32e130f2bc3308c42ca980 | DF20: 0
A21: 45718.438 | B21: 45718.453 | C21: 0 | D21: 100.1.103.81 | E21: 100 | F21: 1295 | G21: 1 | H21: 45718.453 | I21: R_1rYPsnL5gvUgEpI | N21: 40.6342 | O21: -74.2427 | P21: anonymous | Q21: EN | R21: 1 | S21: 5fe17e28d8918b3fae67ec4d | T21: 1 | U21: 5 | V21: Apartment | W21: 1 | Y21: 2 | Z21: 1 | AA21: 1 | AB21: 1 | AC21: 1 | AD21: 2 | AE21: 1 | AF21: 2 | AG21: 2 | AH21: 2 | AI21: 2 | AJ21: 1 | AS21: 4 | AT21: 4 | AU21: 3 | AV21: 5 | AW21: 3 | AX21: 4 | AY21: 4 | AZ21: 4 | BA21: 3 | BB21: 3 | BC21: 3 | BD21: 5 | BE21: 5 | BF21: 5 | BG21: 3 | BH21: 5 | BI21: 5 | BJ21: 5 | BK21: 3 | BL21: 4 | BM21: 3 | BN21: 4 | BO21: 4 | BP21: 3 | BQ21: 4 | BR21: 4 | BS21: 3 | BT21: 5 | BU21: 4 | BV21: 4 | BW21: 4 | BX21: 4 | BY21: 3 | BZ21: 5 | CA21: 5 | CB21: 3 | CC21: 4 | CD21: 4 | CE21: 4 | CF21: 4 | CG21: 5 | CL21: 4 | CQ21: 2 | CS21: 3 | CT21: 2 | CU21: 2 | CV21: 2 | CX21: 1 | CY21: 2 | CZ21: 8 | DA21: Self Employed | DB21: 7 | DC21: 07203 | DE21: 5fe17e28d8918b3fae67ec4d | DF21: 0
A22: 45718.448 | B22: 45718.453 | C22: 0 | D22: 24.45.107.178 | E22: 100 | F22: 401 | G22: 1 | H22: 45718.453 | I22: R_8rPdCIJV9rEWXdd | N22: 40.9451 | O22: -74.2531 | P22: anonymous | Q22: EN | R22: 1 | S22: 673248c019806a9412a13c6a | T22: 1 | U22: 1 | W22: 2 | Y22: 1 | Z22: 2 | AA22: 1 | AB22: 2 | AC22: 2 | AD22: 2 | AE22: 1 | AF22: 2 | AG22: 2 | AH22: 2 | AI22: 2 | AJ22: 1 | AS22: 2 | AT22: 2 | AU22: 2 | AV22: 2 | AW22: 2 | AX22: 3 | AY22: 1 | AZ22: 1 | BA22: 1 | BB22: 1 | BC22: 1 | BD22: 1 | BE22: 1 | BF22: 4 | BG22: 3 | BH22: 4 | BI22: 4 | BJ22: 3 | BK22: 3 | BL22: 3 | BM22: 4 | BN22: 2 | BO22: 4 | BP22: 4 | BQ22: 4 | BR22: 5 | BS22: 3 | BT22: 3 | BU22: 3 | BV22: 4 | BW22: 4 | BX22: 4 | BY22: 4 | BZ22: 3 | CA22: 3 | CB22: 3 | CC22: 1 | CD22: 3 | CE22: 4 | CF22: 2 | CG22: 1 | CH22: 1 | CI22: 1 | CJ22: 4 | CK22: 3 | CM22: 2 | CN22: 4 | CO22: 3 | CP22: 1 | CQ22: 2 | CS22: 2 | CT22: 3 | CU22: 4 | CV22: 1 | CX22: 1 | CY22: 1 | CZ22: 8 | DA22: Consulting | DB22: 10 | DC22: 07055 | DE22: 673248c019806a9412a13c6a | DF22: 0
A23: 45718.448 | B23: 45718.453 | C23: 0 | D23: 73.197.61.23 | E23: 100 | F23: 463 | G23: 1 | H23: 45718.454 | I23: R_5gUbb8dSsYwb7fo | N23: 39.9152 | O23: -75.0739 | P23: anonymous | Q23: EN | R23: 1 | S23: 66d9e222230df4e7c576f1b2 | T23: 1 | U23: 1 | W23: 1 | Y23: 1 | Z23: 2 | AA23: 1 | AB23: 1 | AC23: 4 | AD23: 3 | AE23: 1 | AF23: 2 | AG23: 1 | AH23: 2 | AI23: 1 | AJ23: 2 | AK23: 1 | AL23: 2 | AN23: 5 | AO23: 2 | AP23: 5 | AR23: 1 | AS23: 4 | AT23: 4 | AU23: 4 | AV23: 4 | AW23: 4 | AX23: 4 | AY23: 4 | AZ23: 4 | BA23: 4 | BB23: 3 | BC23: 4 | BD23: 1 | BE23: 4 | BF23: 2 | BG23: 1 | BH23: 4 | BI23: 4 | BJ23: 4 | BK23: 4 | BL23: 4 | BM23: 4 | BN23: 2 | BO23: 4 | BP23: 4 | BQ23: 4 | BR23: 3 | BS23: 3 | BT23: 4 | BU23: 4 | BV23: 3 | BW23: 2 | BX23: 3 | BY23: 3 | BZ23: 1 | CA23: 3 | CB23: 3 | CC23: 1 | CD23: 3 | CE23: 1 | CF23: 3 | CG23: 1 | CL23: 3 | CQ23: 1 | CS23: 3 | CT23: 2 | CU23: 4 | CV23: 1 | CX23: 1 | CY23: 1 | CZ23: 8 | DB23: 7 | DC23: 08107 | DE23: 66d9e222230df4e7c576f1b2 | DF23: 0
A24: 45718.437 | B24: 45718.454 | C24: 0 | D24: 97.216.98.43 | E24: 100 | F24: 1506 | G24: 1 | H24: 45718.454 | I24: R_7qvLwtxdOOTTTKP | N24: 40.5995 | O24: -75.3763 | P24: anonymous | Q24: EN | R24: 1 | S24: 666c44e0af1439ede48b2d93 | T24: 1 | U24: 2 | W24: 1 | Y24: 7 | Z24: 1 | AA24: 1 | AB24: 2 | AC24: 2 | AD24: 3 | AE24: 1 | AF24: 2 | AG24: 1 | AH24: 2 | AI24: 2 | AJ24: 1 | AS24: 3 | AT24: 3 | AU24: 4 | AV24: 3 | AW24: 2 | AX24: 3 | AY24: 2 | AZ24: 2 | BA24: 3 | BB24: 3 | BC24: 2 | BD24: 3 | BE24: 3 | BF24: 4 | BG24: 2 | BH24: 4 | BI24: 3 | BJ24: 3 | BK24: 4 | BL24: 2 | BM24: 3 | BN24: 3 | BO24: 4 | BP24: 3 | BQ24: 3 | BR24: 2 | BS24: 3 | BT24: 3 | BU24: 4 | BV24: 4 | BW24: 3 | BX24: 4 | BY24: 4 | BZ24: 3 | CA24: 3 | CB24: 4 | CC24: 3 | CD24: 3 | CE24: 4 | CF24: 3 | CG24: 2 | CL24: 4 | CQ24: 1 | CS24: 2 | CT24: 3 | CU24: 1 | CV24: 1 | CX24: 1 | CY24: 1 | CZ24: 6 | DB24: 9 | DC24: 07522 | DE24: 666c44e0af1439ede48b2d93 | DF24: 0
A25: 45718.449 | B25: 45718.455 | C25: 0 | D25: 71.187.58.246 | E25: 100 | F25: 480 | G25: 1 | H25: 45718.455 | I25: R_3liyglzDTPXMRxI | N25: 40.8897 | O25: -74.4847 | P25: anonymous | Q25: EN | R25: 1 | S25: 66d62734985c822b67585824 | T25: 1 | U25: 1 | W25: 2 | Y25: 4 | Z25: 1 | AA25: 1 | AB25: 1 | AC25: 5 | AD25: 2 | AE25: 1 | AF25: 2 | AG25: 1 | AH25: 1 | AI25: 1 | AJ25: 2 | AK25: 1 | AL25: 2 | AN25: 2 | AO25: 2 | AP25: 4 | AQ25: trenches | AR25: 2 | AS25: 5 | AT25: 5 | AU25: 5 | AV25: 5 | AW25: 5 | AX25: 4 | AY25: 4 | AZ25: 5 | BA25: 5 | BB25: 5 | BC25: 5 | BD25: 4 | BE25: 4 | BF25: 5 | BG25: 3 | BH25: 3 | BI25: 4 | BJ25: 5 | BK25: 5 | BL25: 5 | BM25: 5 | BN25: 5 | BO25: 3 | BP25: 4 | BQ25: 4 | BR25: 4 | BS25: 3 | BT25: 5 | BU25: 4 | BV25: 2 | BW25: 1 | BX25: 2 | BY25: 4 | BZ25: 2 | CA25: 2 | CB25: 4 | CC25: 2 | CD25: 2 | CE25: 3 | CF25: 4 | CG25: 1 | CH25: 3 | CI25: 2 | CJ25: 2 | CK25: 3 | CM25: 1 | CN25: 3 | CO25: 4 | CP25: 2 | CQ25: 2 | CS25: 6 | CT25: 4 | CU25: 4 | CV25: 4 | CX25: 1 | CY25: 2 | CZ25: 4 | DB25: 10 | DC25: 07834 | DE25: 66d62734985c822b67585824 | DF25: 0
A26: 45718.451 | B26: 45718.455 | C26: 0 | D26: 173.70.93.189 | E26: 100 | F26: 357 | G26: 1 | H26: 45718.455 | I26: R_6lZCLQhEvYvmac1 | N26: 40.7938 | O26: -74.4878 | P26: anonymous | Q26: EN | R26: 1 | S26: 6785ca7bd996dd759b99217c | T26: 1 | U26: 1 | W26: 1 | Y26: 4 | Z26: 2 | AA26: 1 | AB26: 2 | AC26: 5 | AD26: 2 | AE26: 1 | AF26: 2 | AG26: 1 | AH26: 2 | AI26: 2 | AJ26: 1 | AS26: 4 | AT26: 4 | AU26: 4 | AV26: 4 | AW26: 4 | AX26: 4 | AY26: 3 | AZ26: 3 | BA26: 4 | BB26: 4 | BC26: 2 | BD26: 4 | BE26: 2 | BF26: 5 | BG26: 2 | BH26: 4 | BI26: 2 | BJ26: 2 | BK26: 2 | BL26: 2 | BM26: 2 | BN26: 2 | BO26: 4 | BP26: 4 | BQ26: 4 | BR26: 4 | BS26: 3 | BT26: 2 | BU26: 2 | BV26: 4 | BW26: 4 | BX26: 4 | BY26: 5 | BZ26: 4 | CA26: 4 | CB26: 4 | CC26: 2 | CD26: 4 | CE26: 4 | CF26: 3 | CG26: 1 | CL26: 1 | CQ26: 1 | CS26: 1 | CT26: 2 | CU26: 4 | CV26: 3 | CX26: 1 | CY26: 2 | CZ26: 3 | DB26: 10 | DC26: 07960 | DE26: 6785ca7bd996dd759b99217c | DF26: 0
A27: 45718.446 | B27: 45718.455 | C27: 0 | D27: 68.198.232.88 | E27: 100 | F27: 840 | G27: 1 | H27: 45718.455 | I27: R_5GLWmm5OtVYqHbH | N27: 41.5965 | O27: -73.911 | P27: anonymous | Q27: EN | R27: 1 | S27: 677618e6c8caeb6caebd74a3 | T27: 2 | U27: 3 | W27: 2 | Y27: 3 | Z27: 1 | AA27: 1 | AB27: 1 | AC27: 2 | AD27: 4 | AE27: 1 | AF27: 2 | AG27: 2 | AH27: 1 | AI27: 2 | AJ27: 1 | AS27: 3 | AT27: 4 | AU27: 4 | AV27: 4 | AW27: 4 | AX27: 4 | AY27: 3 | AZ27: 3 | BA27: 3 | BB27: 2 | BC27: 3 | BD27: 2 | BE27: 2 | BF27: 4 | BG27: 1 | BH27: 3 | BI27: 3 | BJ27: 3 | BK27: 4 | BL27: 4 | BM27: 4 | BN27: 4 | BO27: 3 | BP27: 3 | BQ27: 4 | BR27: 2 | BS27: 3 | BT27: 4 | BU27: 4 | BV27: 3 | BW27: 3 | BX27: 3 | BY27: 3 | BZ27: 3 | CA27: 2 | CB27: 4 | CC27: 3 | CD27: 3 | CE27: 4 | CF27: 3 | CG27: 1 | CH27: 3 | CI27: 1 | CJ27: 4 | CK27: 4 | CM27: 2 | CN27: 3 | CO27: 1 | CP27: 4 | CQ27: 1 | CS27: 6 | CT27: 3 | CU27: 1 | CV27: 2 | CX27: 1 | CY27: 2 | CZ27: 2 | DB27: 6 | DC27: 10516 | DE27: 677618e6c8caeb6caebd74a3 | DF27: 0
A28: 45718.452 | B28: 45718.456 | C28: 0 | D28: 172.56.34.232 | E28: 100 | F28: 378 | G28: 1 | H28: 45718.456 | I28: R_1DAbsY8hNr79C9I | N28: 40.7252 | O28: -73.944 | P28: anonymous | Q28: EN | R28: 1 | S28: 67670cf22cf98294c8fbcfbc | T28: 2 | U28: 1 | W28: 1 | Y28: 4 | Z28: 1 | AA28: 1 | AB28: 1 | AC28: 2 | AD28: 2 | AE28: 2 | AF28: 2 | AG28: 2 | AH28: 2 | AI28: 1 | AJ28: 2 | AK28: 3 | AL28: 1 | AN28: 2 | AO28: 1 | AP28: 1 | AR28: 2 | AS28: 5 | AT28: 5 | AU28: 5 | AV28: 5 | AW28: 5 | AX28: 4 | AY28: 5 | AZ28: 5 | BA28: 5 | BB28: 5 | BC28: 5 | BD28: 5 | BE28: 4 | BF28: 4 | BG28: 5 | BH28: 5 | BI28: 5 | BJ28: 5 | BK28: 5 | BL28: 5 | BM28: 5 | BN28: 5 | BO28: 5 | BP28: 5 | BQ28: 5 | BR28: 4 | BS28: 3 | BT28: 5 | BU28: 5 | BV28: 4 | BW28: 4 | BX28: 5 | BY28: 5 | BZ28: 5 | CA28: 4 | CB28: 4 | CC28: 4 | CD28: 4 | CE28: 1 | CF28: 3 | CG28: 4 | CL28: 4 | CQ28: 1 | CS28: 3 | CT28: 4 | CU28: 2 | CV28: 1 | CX28: 1 | CY28: 1 | CZ28: 2 | DB28: 10 | DC28: 10007 | DE28: 67670cf22cf98294c8fbcfbc | DF28: 0
A29: 45718.453 | B29: 45718.457 | C29: 0 | D29: 100.33.47.210 | E29: 100 | F29: 288 | G29: 1 | H29: 45718.457 | I29: R_3KKRE7EjOiT1EfD | N29: 40.6952 | O29: -73.6596 | P29: anonymous | Q29: EN | R29: 1 | S29: 6647b8648a67a4ef6585458a | T29: 2 | U29: 1 | W29: 4 | X29: live with partner who owns | Y29: 1 | Z29: 2 | AA29: 1 | AB29: 2 | AC29: 2 | AD29: 2 | AE29: 1 | AF29: 2 | AG29: 2 | AH29: 2 | AI29: 2 | AJ29: 1 | AS29: 4 | AT29: 4 | AU29: 5 | AV29: 5 | AW29: 4 | AX29: 3 | AY29: 2 | AZ29: 2 | BA29: 3 | BB29: 3 | BC29: 1 | BD29: 1 | BE29: 4 | BF29: 3 | BG29: 1 | BH29: 1 | BI29: 1 | BJ29: 2 | BK29: 2 | BL29: 2 | BM29: 2 | BN29: 1 | BO29: 1 | BP29: 2 | BQ29: 2 | BR29: 1 | BS29: 3 | BT29: 1 | BU29: 1 | BV29: 4 | BW29: 3 | BX29: 4 | BY29: 5 | BZ29: 3 | CA29: 4 | CB29: 4 | CC29: 3 | CD29: 3 | CE29: 4 | CF29: 4 | CG29: 2 | CQ29: 1 | CS29: 2 | CT29: 2 | CU29: 3 | CV29: 5 | CW29: self employed | CX29: 1 | CY29: 2 | CZ29: 8 | DA29: online sales | DB29: 1 | DC29: 11554 | DE29: 6647b8648a67a4ef6585458a | DF29: 0
A30: 45718.443 | B30: 45718.457 | C30: 0 | D30: 73.29.45.64 | E30: 100 | F30: 1196 | G30: 1 | H30: 45718.457 | I30: R_7Us9ZnBCXDFuPWV | N30: 40.8566 | O30: -74.8389 | P30: anonymous | Q30: EN | R30: 1 | S30: 65e235e4ac7b9bc14ae3e92e | T30: 1 | U30: 1 | W30: 2 | Y30: 2 | Z30: 1 | AA30: 1 | AB30: 2 | AC30: 5 | AD30: 4 | AE30: 1 | AF30: 1 | AG30: 1 | AH30: 2 | AI30: 2 | AJ30: 1 | AS30: 5 | AT30: 5 | AU30: 5 | AV30: 5 | AW30: 5 | AX30: 5 | AY30: 5 | AZ30: 5 | BA30: 5 | BB30: 5 | BC30: 5 | BD30: 5 | BE30: 5 | BF30: 5 | BG30: 5 | BH30: 2 | BI30: 2 | BJ30: 4 | BK30: 4 | BL30: 5 | BM30: 4 | BN30: 4 | BO30: 2 | BP30: 2 | BQ30: 2 | BR30: 2 | BS30: 3 | BT30: 4 | BU30: 4 | BV30: 1 | BW30: 1 | BX30: 3 | BY30: 4 | BZ30: 2 | CA30: 4 | CB30: 4 | CC30: 3 | CD30: 5 | CE30: 4 | CF30: 2 | CG30: 3 | CH30: 1 | CI30: 2 | CJ30: 1 | CK30: 2 | CM30: 1 | CN30: 2 | CO30: 4 | CP30: 3 | CQ30: 5 | CR30: non binary | CS30: 2 | CT30: 3 | CU30: 3 | CV30: 1 | CX30: 1 | CY30: 2 | CZ30: 2 | DB30: 10 | DC30: 07840 | DE30: 65e235e4ac7b9bc14ae3e92e | DF30: 0
A31: 45718.453 | B31: 45718.457 | C31: 0 | D31: 68.174.198.200 | E31: 100 | F31: 335 | G31: 1 | H31: 45718.457 | I31: R_5S81XwVoPSccmwp | N31: 40.7484 | O31: -73.862 | P31: anonymous | Q31: EN | R31: 1 | S31: 66b963229da98baf6c9d457d | T31: 2 | U31: 3 | W31: 2 | Y31: 1 | Z31: 2 | AA31: 1 | AB31: 2 | AC31: 2 | AD31: 5 | AE31: 1 | AF31: 2 | AG31: 1 | AH31: 2 | AI31: 2 | AJ31: 1 | AS31: 2 | AT31: 2 | AU31: 4 | AV31: 3 | AW31: 3 | AX31: 4 | AY31: 2 | AZ31: 2 | BA31: 2 | BB31: 2 | BC31: 3 | BD31: 1 | BE31: 3 | BF31: 4 | BG31: 1 | BH31: 2 | BI31: 2 | BJ31: 3 | BK31: 3 | BL31: 2 | BM31: 2 | BN31: 2 | BO31: 2 | BP31: 2 | BQ31: 2 | BR31: 2 | BS31: 3 | BT31: 2 | BU31: 2 | BV31: 2 | BW31: 2 | BX31: 1 | BY31: 3 | BZ31: 3 | CA31: 2 | CB31: 3 | CC31: 3 | CD31: 1 | CE31: 1 | CF31: 4 | CG31: 1 | CH31: 1 | CI31: 1 | CJ31: 3 | CK31: 1 | CM31: 2 | CN31: 3 | CO31: 1 | CP31: 4 | CQ31: 2 | CS31: 4 | CT31: 2 | CU31: 4 | CV31: 1 | CX31: 1 | CY31: 2 | CZ31: 8 | DA31: technology | DB31: 10 | DC31: 11372 | DE31: 66b963229da98baf6c9d457d | DF31: 0
A32: 45718.454 | B32: 45718.459 | C32: 0 | D32: 174.166.162.165 | E32: 100 | F32: 442 | G32: 1 | H32: 45718.459 | I32: R_1Hq3RYDnjMEYzGj | N32: 40.4668 | O32: -74.6607 | P32: anonymous | Q32: EN | R32: 1 | S32: 5f4f9bc1f7598f06b2dc816f | T32: 1 | U32: 1 | W32: 3 | Y32: 4 | Z32: 1 | AA32: 1 | AB32: 2 | AC32: 2 | AD32: 3 | AE32: 1 | AF32: 2 | AG32: 2 | AH32: 1 | AI32: 2 | AJ32: 1 | AS32: 4 | AT32: 4 | AU32: 4 | AV32: 4 | AW32: 2 | AX32: 4 | AY32: 1 | AZ32: 3 | BA32: 2 | BB32: 2 | BC32: 4 | BD32: 2 | BE32: 4 | BF32: 2 | BG32: 1 | BH32: 2 | BI32: 2 | BJ32: 2 | BK32: 4 | BL32: 2 | BM32: 2 | BN32: 2 | BO32: 2 | BP32: 2 | BQ32: 2 | BR32: 2 | BS32: 3 | BT32: 2 | BU32: 2 | BV32: 2 | BW32: 2 | BX32: 2 | BY32: 4 | BZ32: 2 | CA32: 2 | CB32: 4 | CC32: 2 | CD32: 2 | CE32: 4 | CF32: 2 | CG32: 1 | CH32: 2 | CI32: 1 | CJ32: 2 | CK32: 3 | CM32: 2 | CN32: 4 | CO32: 3 | CP32: 1 | CQ32: 2 | CS32: 6 | CT32: 4 | CU32: 4 | CV32: 4 | CX32: 1 | CY32: 2 | CZ32: 8 | DA32: Tech | DB32: 10 | DC32: 07052 | DE32: 5f4f9bc1f7598f06b2dc816f | DF32: 0
A33: 45718.456 | B33: 45718.459 | C33: 0 | D33: 47.18.97.210 | E33: 100 | F33: 291 | G33: 1 | H33: 45718.459 | I33: R_6Lh77PphWYamqEa | N33: 40.5802 | O33: -74.3594 | P33: anonymous | Q33: EN | R33: 1 | S33: 67ad00c159b7e9d25ec4e04c | T33: 1 | U33: 1 | W33: 2 | Y33: 5 | Z33: 2 | AA33: 1 | AB33: 1 | AC33: 4 | AD33: 4 | AE33: 1 | AF33: 2 | AG33: 2 | AH33: 2 | AI33: 2 | AJ33: 1 | AS33: 4 | AT33: 4 | AU33: 3 | AV33: 3 | AW33: 3 | AX33: 4 | AY33: 2 | AZ33: 3 | BA33: 3 | BB33: 3 | BC33: 4 | BD33: 4 | BE33: 3 | BF33: 5 | BG33: 3 | BH33: 5 | BI33: 2 | BJ33: 2 | BK33: 2 | BL33: 2 | BM33: 2 | BN33: 1 | BO33: 1 | BP33: 1 | BQ33: 2 | BR33: 4 | BS33: 3 | BT33: 1 | BU33: 1 | BV33: 4 | BW33: 3 | BX33: 3 | BY33: 4 | BZ33: 2 | CA33: 2 | CB33: 4 | CC33: 2 | CD33: 3 | CE33: 4 | CF33: 1 | CG33: 1 | CH33: 4 | CI33: 1 | CJ33: 3 | CK33: 3 | CM33: 1 | CN33: 2 | CO33: 3 | CP33: 4 | CQ33: 1 | CS33: 1 | CT33: 3 | CU33: 1 | CV33: 5 | CW33: Student | CX33: 1 | CY33: 1 | CZ33: 3 | DB33: 10 | DC33: 08902 | DE33: 67ad00c159b7e9d25ec4e04c | DF33: 0
A34: 45718.434 | B34: 45718.46 | C34: 0 | D34: 172.59.211.131 | E34: 100 | F34: 2243 | G34: 1 | H34: 45718.46 | I34: R_1MoHhb8nOc7fyiR | N34: 40.7463 | O34: -74.1553 | P34: anonymous | Q34: EN | R34: 1 | S34: 67be05692b18b631ece5fd2e | T34: 1 | U34: 2 | W34: 1 | Y34: 5 | Z34: 2 | AA34: 1 | AB34: 1 | AC34: 4 | AD34: 2 | AE34: 1 | AF34: 1 | AG34: 2 | AH34: 2 | AI34: 2 | AJ34: 1 | AS34: 3 | AT34: 4 | AU34: 4 | AV34: 4 | AW34: 4 | AX34: 4 | AY34: 4 | AZ34: 5 | BA34: 5 | BB34: 4 | BC34: 4 | BD34: 5 | BE34: 5 | BF34: 5 | BG34: 4 | BH34: 4 | BI34: 4 | BJ34: 3 | BK34: 4 | BL34: 4 | BM34: 4 | BN34: 4 | BO34: 4 | BP34: 4 | BQ34: 4 | BR34: 4 | BS34: 3 | BT34: 4 | BU34: 4 | BV34: 4 | BW34: 5 | BX34: 4 | BY34: 4 | BZ34: 4 | CA34: 5 | CB34: 5 | CC34: 4 | CD34: 5 | CE34: 4 | CF34: 4 | CG34: 1 | CL34: 1 | CQ34: 1 | CS34: 1 | CT34: 4 | CU34: 4 | CV34: 1 | CX34: 1 | CY34: 1 | CZ34: 4 | DB34: 7 | DC34: 07206 | DE34: 67be05692b18b631ece5fd2e | DF34: 0
A35: 45718.45 | B35: 45718.46 | C35: 0 | D35: 216.59.90.100 | E35: 100 | F35: 939 | G35: 1 | H35: 45718.46 | I35: R_8PGhRhNqdcHJ29r | N35: 42.1254 | O35: -75.9664 | P35: anonymous | Q35: EN | R35: 1 | S35: 669aabcd5c4869b3bb6d7761 | T35: 2 | U35: 1 | W35: 2 | Y35: 1 | Z35: 1 | AA35: 1 | AB35: 2 | AC35: 4 | AD35: 3 | AE35: 1 | AF35: 1 | AG35: 1 | AH35: 2 | AI35: 2 | AJ35: 1 | AS35: 3 | AT35: 4 | AU35: 4 | AV35: 4 | AW35: 4 | AX35: 4 | AY35: 3 | AZ35: 4 | BA35: 4 | BB35: 4 | BC35: 2 | BD35: 4 | BE35: 4 | BF35: 4 | BG35: 4 | BH35: 2 | BI35: 2 | BJ35: 2 | BK35: 4 | BL35: 4 | BM35: 4 | BN35: 4 | BO35: 4 | BP35: 3 | BQ35: 2 | BR35: 2 | BS35: 3 | BT35: 3 | BU35: 2 | BV35: 4 | BW35: 3 | BX35: 4 | BY35: 4 | BZ35: 2 | CA35: 3 | CB35: 5 | CC35: 4 | CD35: 4 | CE35: 4 | CF35: 1 | CG35: 1 | CH35: 4 | CI35: 2 | CJ35: 4 | CK35: 4 | CM35: 2 | CN35: 4 | CO35: 3 | CP35: 1 | CQ35: 1 | CS35: 3 | CT35: 3 | CU35: 4 | CV35: 2 | CX35: 1 | CY35: 1 | CZ35: 8 | DA35: Religious | DB35: 10 | DC35: 13760 | DD35: Add a section for community college level education. I have a two year associates degree. | DE35: 669aabcd5c4869b3bb6d7761 | DF35: 0
A36: 45718.455 | B36: 45718.461 | C36: 0 | D36: 73.226.240.208 | E36: 100 | F36: 500 | G36: 1 | H36: 45718.461 | I36: R_3oXUSI5RONhDdLb | N36: 40.7238 | O36: -74.2293 | P36: anonymous | Q36: EN | R36: 1 | S36: 660ec4452539f6860b02db7a | T36: 1 | U36: 1 | W36: 2 | Y36: 1 | Z36: 1 | AA36: 1 | AB36: 2 | AC36: 4 | AD36: 3 | AE36: 1 | AF36: 1 | AG36: 1 | AH36: 2 | AI36: 1 | AJ36: 2 | AK36: 1 | AL36: 1 | AM36: 2024 | AN36: 2 | AO36: 2 | AP36: 4 | AQ36: Fix sump pump | AR36: 1 | AS36: 4 | AT36: 4 | AU36: 4 | AV36: 4 | AW36: 3 | AX36: 3 | AY36: 2 | AZ36: 3 | BA36: 4 | BB36: 5 | BC36: 3 | BD36: 1 | BE36: 1 | BF36: 4 | BG36: 2 | BH36: 2 | BI36: 4 | BJ36: 4 | BK36: 4 | BL36: 3 | BM36: 3 | BN36: 2 | BO36: 1 | BP36: 4 | BQ36: 4 | BR36: 4 | BS36: 3 | BT36: 2 | BU36: 4 | BV36: 2 | BW36: 2 | BX36: 1 | BY36: 2 | BZ36: 2 | CA36: 4 | CB36: 5 | CC36: 2 | CD36: 3 | CE36: 4 | CF36: 1 | CG36: 1 | CH36: 2 | CI36: 1 | CJ36: 4 | CK36: 5 | CM36: 4 | CN36: 3 | CO36: 1 | CP36: 2 | CQ36: 2 | CS36: 3 | CT36: 3 | CU36: 4 | CV36: 1 | CX36: 1 | CY36: 1 | CZ36: 6 | DB36: 10 | DC36: 07033 | DE36: 660ec4452539f6860b02db7a | DF36: 0
A37: 45718.453 | B37: 45718.461 | C37: 0 | D37: 75.208.4.36 | E37: 100 | F37: 665 | G37: 1 | H37: 45718.461 | I37: R_5clmEpgYZUy7Ovv | N37: 35.8677 | O37: -86.4174 | P37: anonymous | Q37: EN | R37: 1 | S37: 67a9addacffc14df077673fe | T37: 1 | U37: 1 | W37: 2 | Y37: 1 | Z37: 2 | AA37: 1 | AB37: 2 | AC37: 8 | AD37: 5 | AE37: 1 | AF37: 2 | AG37: 1 | AH37: 2 | AI37: 1 | AJ37: 2 | AK37: 2 | AL37: 1 | AM37: 2021 | AN37: 2 | AO37: 2 | AP37: 5 | AR37: 1 | AS37: 4 | AT37: 4 | AU37: 4 | AV37: 4 | AW37: 4 | AX37: 5 | AY37: 3 | AZ37: 3 | BA37: 3 | BB37: 3 | BC37: 2 | BD37: 2 | BE37: 3 | BF37: 4 | BG37: 2 | BH37: 5 | BI37: 3 | BJ37: 2 | BK37: 2 | BL37: 2 | BM37: 2 | BN37: 2 | BO37: 3 | BP37: 3 | BQ37: 4 | BR37: 2 | BS37: 3 | BT37: 2 | BU37: 2 | BV37: 4 | BW37: 3 | BX37: 2 | BY37: 4 | BZ37: 3 | CA37: 2 | CB37: 4 | CC37: 3 | CD37: 2 | CE37: 4 | CF37: 2 | CG37: 1 | CH37: 2 | CI37: 1 | CJ37: 2 | CK37: 4 | CM37: 2 | CN37: 3 | CO37: 4 | CP37: 1 | CQ37: 1 | CS37: 1 | CT37: 2 | CU37: 4 | CV37: 5 | CW37: Student | CX37: 1 | CY37: 1 | CZ37: 8 | DA37: Student | DB37: 10 | DC37: 07044 | DE37: 67a9addacffc14df077673fe | DF37: 0
A38: 45718.456 | B38: 45718.461 | C38: 0 | D38: 173.70.61.204 | E38: 100 | F38: 463 | G38: 1 | H38: 45718.461 | I38: R_3v6lRkl3O5SDcbL | N38: 40.8177 | O38: -73.9771 | P38: anonymous | Q38: EN | R38: 1 | S38: 5e35e01b5bfa43595d69621d | T38: 1 | U38: 2 | W38: 2 | Y38: 1 | Z38: 2 | AA38: 1 | AB38: 2 | AC38: 7 | AD38: 6 | AE38: 3 | AF38: 2 | AG38: 1 | AH38: 2 | AI38: 1 | AJ38: 2 | AK38: 4 | AL38: 1 | AM38: none | AN38: 2 | AO38: 2 | AP38: 5 | AR38: 1 | AS38: 4 | AT38: 4 | AU38: 5 | AV38: 5 | AW38: 2 | AX38: 3 | AY38: 4 | AZ38: 5 | BA38: 5 | BB38: 5 | BC38: 3 | BD38: 2 | BE38: 4 | BF38: 5 | BG38: 3 | BH38: 4 | BI38: 4 | BJ38: 3 | BK38: 2 | BL38: 1 | BM38: 3 | BN38: 2 | BO38: 4 | BP38: 5 | BQ38: 5 | BR38: 2 | BS38: 3 | BT38: 2 | BU38: 2 | BV38: 1 | BW38: 2 | BX38: 3 | BY38: 4 | BZ38: 2 | CA38: 1 | CB38: 2 | CC38: 1 | CD38: 1 | CE38: 1 | CF38: 3 | CG38: 2 | CH38: 3 | CI38: 1 | CJ38: 2 | CK38: 4 | CM38: 1 | CN38: 4 | CO38: 2 | CP38: 3 | CQ38: 1 | CS38: 4 | CT38: 2 | CU38: 4 | CV38: 1 | CX38: 1 | CY38: 2 | CZ38: 3 | DB38: 10 | DC38: 07010 | DE38: 5e35e01b5bfa43595d69621d | DF38: 0
A39: 45718.449 | B39: 45718.462 | C39: 0 | D39: 108.27.129.2 | E39: 100 | F39: 1111 | G39: 1 | H39: 45718.462 | I39: R_3rccvsqNdiu4z1t | N39: 40.5828 | O39: -73.9532 | P39: anonymous | Q39: EN | R39: 1 | S39: 5b4991de56e0140001acb76b | T39: 2 | U39: 3 | W39: 1 | Y39: 2 | Z39: 1 | AA39: 1 | AB39: 2 | AC39: 4 | AD39: 4 | AE39: 2 | AF39: 2 | AG39: 2 | AH39: 2 | AI39: 1 | AJ39: 2 | AK39: 2 | AL39: 1 | AM39: 2023 | AN39: 2 | AO39: 2 | AP39: 3 | AR39: 1 | AS39: 4 | AT39: 3 | AU39: 4 | AV39: 3 | AW39: 3 | AX39: 4 | AY39: 3 | AZ39: 4 | BA39: 3 | BB39: 4 | BC39: 5 | BD39: 4 | BE39: 4 | BF39: 3 | BG39: 3 | BH39: 4 | BI39: 3 | BJ39: 4 | BK39: 4 | BL39: 4 | BM39: 5 | BN39: 4 | BO39: 4 | BP39: 4 | BQ39: 3 | BR39: 4 | BS39: 3 | BT39: 3 | BU39: 3 | BV39: 4 | BW39: 3 | BX39: 4 | BY39: 4 | BZ39: 3 | CA39: 4 | CB39: 3 | CC39: 4 | CD39: 4 | CE39: 1 | CF39: 4 | CG39: 1 | CL39: 3 | CQ39: 2 | CS39: 1 | CT39: 3 | CU39: 1 | CV39: 1 | CX39: 1 | CY39: 1 | CZ39: 4 | DB39: 7 | DC39: 11229 | DE39: 5b4991de56e0140001acb76b | DF39: 0
A40: 45718.457 | B40: 45718.463 | C40: 0 | D40: 76.37.0.39 | E40: 100 | F40: 452 | G40: 1 | H40: 45718.463 | I40: R_6c6BsxgV6QyXN05 | N40: 42.7227 | O40: -73.8178 | P40: anonymous | Q40: EN | R40: 1 | S40: 663e3c2870a87bac315ac450 | T40: 2 | U40: 1 | W40: 2 | Y40: 1 | Z40: 1 | AA40: 1 | AB40: 2 | AC40: 2 | AD40: 2 | AE40: 1 | AF40: 2 | AG40: 2 | AH40: 2 | AI40: 2 | AJ40: 1 | AS40: 4 | AT40: 4 | AU40: 5 | AV40: 5 | AW40: 4 | AX40: 3 | AY40: 4 | AZ40: 4 | BA40: 5 | BB40: 4 | BC40: 3 | BD40: 4 | BE40: 4 | BF40: 4 | BG40: 3 | BH40: 3 | BI40: 2 | BJ40: 2 | BK40: 4 | BL40: 4 | BM40: 3 | BN40: 3 | BO40: 3 | BP40: 3 | BQ40: 4 | BR40: 3 | BS40: 3 | BT40: 3 | BU40: 2 | BV40: 4 | BW40: 2 | BX40: 2 | BY40: 3 | BZ40: 2 | CA40: 2 | CB40: 3 | CC40: 1 | CD40: 3 | CE40: 4 | CF40: 4 | CG40: 1 | CH40: 3 | CI40: 2 | CJ40: 4 | CK40: 4 | CM40: 1 | CN40: 2 | CO40: 3 | CP40: 4 | CQ40: 1 | CS40: 1 | CT40: 3 | CU40: 4 | CV40: 1 | CX40: 1 | CY40: 2 | CZ40: 5 | DB40: 10 | DC40: 12208 | DE40: 663e3c2870a87bac315ac450 | DF40: 0
...

Sheet MG
A1: StartDate | B1: EndDate | C1: Status | D1: IPAddress | E1: Progress | F1: Duration (in seconds) | G1: Finished | H1: RecordedDate | I1: ResponseId | J1: RecipientLastName | K1: RecipientFirstName | L1: RecipientEmail | M1: ExternalReference | N1: LocationLatitude | O1: LocationLongitude | P1: DistributionChannel | Q1: UserLanguage | R1: Q1 | S1: Q2 | T1: Q3 | U1: Q4 | V1: Q4_5_TEXT | W1: Q5 | X1: Q5_4_TEXT | Y1: Q6 | Z1: Q7 | AA1: Q8 | AB1: Q9 | AC1: Q10 | AD1: Q11 | AE1: Q12 | AF1: Q13_1 | AG1: Q13_2 | AH1: Q13_3 | AI1: Q14_0 | AJ1: Q14 | AK1: Q15 | AL1: Q16 | AM1: Q16_1_TEXT | AN1: Q17 | AO1: Q18 | AP1: Q19 | AQ1: Q19_4_TEXT | AR1: Q20 | AS1: Q21_1 | AT1: Q21_2 | AU1: Q21_3 | AV1: Q21_4 | AW1: Q21_5 | AX1: Q21_6 | AY1: Q21_7 | AZ1: Q21_8 | BA1: Q21_9 | BB1: Q21_10 | BC1: Q21_11 | BD1: Q21_12 | BE1: Q21_13 | BF1: Q21_14 | BG1: Q21_15 | BH1: Q22_1 | BI1: Q22_2 | BJ1: Q22_3 | BK1: Q22_4 | BL1: Q22_5 | BM1: Q22_6 | BN1: Q22_7 | BO1: Q22_8 | BP1: Q22_9 | BQ1: Q22_10 | BR1: Q22_11 | BS1: Q23 | BT1: Q24_1 | BU1: Q24_2 | BV1: Q25_1 | BW1: Q25_2 | BX1: Q25_3 | BY1: Q25_4 | BZ1: Q25_5 | CA1: Q25_6 | CB1: Q25_7 | CC1: Q25_8 | CD1: Q25_9 | CE1: Q26 | CF1: Q27 | CG1: Q28 | CH1: Q29 | CI1: Q30 | CJ1: Q31 | CK1: Q32 | CL1: Q33 | CM1: Q34_1 | CN1: Q34_2 | CO1: Q34_3 | CP1: Q34_4 | CQ1: Q35 | CR1: Q35_5_TEXT | CS1: Q36 | CT1: Q37 | CU1: Q38 | CV1: Q39 | CW1: Q39_5_TEXT | CX1: Q40 | CY1: Q41 | CZ1: Q42 | DA1: Q42_8_TEXT | DB1: Q43 | DC1: Q44 | DD1: Q45 | DE1: PROLIFIC_PID | DF1: Indicators_Satisfied
A2: 45718.431 | B2: 45718.437 | C2: 0 | D2: 73.248.109.70 | E2: 100 | F2: 524 | G2: 1 | H2: 45718.437 | I2: R_7j7fGoUx2urCdLI | N2: 39.7889 | O2: -74.1982 | P2: anonymous | Q2: EN | R2: 1 | S2: 676c3f1a779ded5787343064 | T2: 1 | U2: 1 | W2: 4 | X2: I live with my parents who own their home. | Y2: 6 | Z2: 2 | AA2: 1 | AB2: 2 | AC2: 3 | AD2: 3 | AE2: 1 | AF2: 2 | AG2: 2 | AH2: 2 | AI2: 2 | AJ2: 1 | AS2: 3 | AT2: 3 | AU2: 3 | AV2: 3 | AW2: 4 | AX2: 3 | AY2: 2 | AZ2: 2 | BA2: 3 | BB2: 3 | BC2: 4 | BD2: 2 | BE2: 4 | BF2: 4 | BG2: 2 | BH2: 4 | BI2: 3 | BJ2: 2 | BK2: 2 | BL2: 2 | BM2: 2 | BN2: 2 | BO2: 4 | BP2: 4 | BQ2: 4 | BR2: 2 | BS2: 3 | BT2: 1 | BU2: 4 | BV2: 2 | BW2: 3 | BX2: 2 | BY2: 4 | BZ2: 4 | CA2: 3 | CB2: 4 | CC2: 3 | CD2: 3 | CE2: 4 | CF2: 2 | CG2: 2 | CQ2: 1 | CS2: 2 | CT2: 2 | CU2: 4 | CV2: 1 | CX2: 1 | CY2: 1 | CZ2: 8 | DA2: veterinarian receptionist | DB2: 4 | DC2: 08758 | DE2: 676c3f1a779ded5787343064 | DF2: 1
A3: 45718.448 | B3: 45718.452 | C3: 0 | D3: 129.21.147.16 | E3: 100 | F3: 310 | G3: 1 | H3: 45718.452 | I3: R_5EXB9X0in8EJLH8 | N3: 43.0801 | O3: -77.6342 | P3: anonymous | Q3: EN | R3: 1 | S3: 656cf11e8c036a31a22e0ccc | T3: 1 | U3: 5 | V3: Apartment | W3: 1 | Y3: 7 | Z3: 2 | AA3: 1 | AB3: 2 | AC3: 4 | AD3: 2 | AE3: 1 | AF3: 2 | AG3: 1 | AH3: 2 | AI3: 2 | AJ3: 1 | AS3: 4 | AT3: 4 | AU3: 4 | AV3: 4 | AW3: 4 | AX3: 3 | AY3: 2 | AZ3: 4 | BA3: 3 | BB3: 4 | BC3: 4 | BD3: 4 | BE3: 4 | BF3: 4 | BG3: 3 | BH3: 2 | BI3: 2 | BJ3: 2 | BK3: 2 | BL3: 2 | BM3: 2 | BN3: 1 | BO3: 2 | BP3: 2 | BQ3: 2 | BR3: 2 | BS3: 3 | BT3: 2 | BU3: 2 | BV3: 4 | BW3: 4 | BX3: 4 | BY3: 4 | BZ3: 4 | CA3: 4 | CB3: 4 | CC3: 4 | CD3: 4 | CE3: 4 | CF3: 2 | CG3: 1 | CL3: 2 | CQ3: 1 | CS3: 1 | CT3: 2 | CU3: 4 | CV3: 3 | CX3: 1 | CY3: 1 | CZ3: 8 | DA3: student | DB3: 2 | DC3: 07920 | DE3: 656cf11e8c036a31a22e0ccc | DF3: 1
A4: 45718.449 | B4: 45718.453 | C4: 0 | D4: 172.59.214.22 | E4: 100 | F4: 333 | G4: 1 | H4: 45718.453 | I4: R_5VqD7RdQwGIfA7U | N4: 40.7597 | O4: -74.1836 | P4: anonymous | Q4: EN | R4: 1 | S4: 6663c5eb2243733847460c5c | T4: 1 | U4: 2 | W4: 1 | Y4: 1 | Z4: 2 | AA4: 2 | AB4: 2 | AC4: 1 | AD4: 7 | AE4: 5 | AF4: 2 | AG4: 2 | AH4: 2 | AI4: 1 | AJ4: 2 | AK4: 2 | AL4: 1 | AM4: Nont | AN4: 4 | AO4: 2 | AP4: 4 | AQ4: Sandbags | AR4: 1 | AS4: 3 | AT4: 4 | AU4: 4 | AV4: 4 | AW4: 4 | AX4: 4 | AY4: 4 | AZ4: 3 | BA4: 4 | BB4: 3 | BC4: 4 | BD4: 3 | BE4: 4 | BF4: 4 | BG4: 3 | BH4: 4 | BI4: 3 | BJ4: 5 | BK4: 5 | BL4: 4 | BM4: 5 | BN4: 5 | BO4: 4 | BP4: 4 | BQ4: 4 | BR4: 2 | BS4: 3 | BT4: 5 | BU4: 5 | BV4: 2 | BW4: 4 | BX4: 4 | BY4: 3 | BZ4: 2 | CA4: 3 | CB4: 2 | CC4: 1 | CD4: 3 | CE4: 4 | CF4: 2 | CG4: 2 | CL4: 4 | CQ4: 2 | CS4: 4 | CT4: 3 | CU4: 2 | CV4: 2 | CX4: 2 | CY4: 1 | CZ4: 6 | DB4: 6 | DC4: 07305 | DE4: 6663c5eb2243733847460c5c | DF4: 1
A5: 45718.438 | B5: 45718.453 | C5: 0 | D5: 172.59.209.180 | E5: 100 | F5: 1322 | G5: 1 | H5: 45718.453 | I5: R_6N4q8RQ3tJfFmH7 | N5: 40.7463 | O5: -74.1553 | P5: anonymous | Q5: EN | R5: 1 | S5: 6766d6be81561a325b3802c9 | T5: 2 | U5: 1 | W5: 3 | Y5: 5 | Z5: 2 | AA5: 1 | AB5: 2 | AC5: 3 | AD5: 4 | AE5: 3 | AF5: 2 | AG5: 1 | AH5: 1 | AI5: 1 | AJ5: 2 | AK5: 7 | AL5: 2 | AN5: 1 | AO5: 2 | AP5: 5 | AR5: 1 | AS5: 4 | AT5: 3 | AU5: 2 | AV5: 3 | AW5: 3 | AX5: 3 | AY5: 3 | AZ5: 3 | BA5: 4 | BB5: 3 | BC5: 3 | BD5: 3 | BE5: 3 | BF5: 4 | BG5: 3 | BH5: 3 | BI5: 4 | BJ5: 3 | BK5: 4 | BL5: 3 | BM5: 4 | BN5: 3 | BO5: 4 | BP5: 3 | BQ5: 4 | BR5: 3 | BS5: 3 | BT5: 3 | BU5: 4 | BV5: 3 | BW5: 4 | BX5: 3 | BY5: 4 | BZ5: 3 | CA5: 4 | CB5: 3 | CC5: 4 | CD5: 3 | CE5: 1 | CF5: 3 | CG5: 4 | CH5: 3 | CI5: 4 | CJ5: 3 | CK5: 3 | CM5: 2 | CN5: 1 | CO5: 3 | CP5: 4 | CQ5: 1 | CS5: 1 | CT5: 3 | CU5: 2 | CV5: 2 | CX5: 1 | CY5: 1 | CZ5: 4 | DB5: 2 | DC5: 10081 | DD5: This survey is good | DE5: 6766d6be81561a325b3802c9 | DF5: 1
A6: 45718.447 | B6: 45718.454 | C6: 0 | D6: 69.207.213.205 | E6: 100 | F6: 642 | G6: 1 | H6: 45718.454 | I6: R_5z8Ywn2drTMmoj1 | N6: 42.4617 | O6: -75.0534 | P6: anonymous | Q6: EN | R6: 1 | S6: 5be0fb420d5adc0001d6d5b7 | T6: 2 | U6: 1 | W6: 2 | Y6: 1 | Z6: 1 | AA6: 1 | AB6: 1 | AC6: 4 | AD6: 3 | AE6: 1 | AF6: 2 | AG6: 1 | AH6: 2 | AI6: 2 | AJ6: 1 | AS6: 5 | AT6: 4 | AU6: 5 | AV6: 5 | AW6: 5 | AX6: 4 | AY6: 5 | AZ6: 5 | BA6: 5 | BB6: 4 | BC6: 4 | BD6: 3 | BE6: 4 | BF6: 5 | BG6: 3 | BH6: 4 | BI6: 3 | BJ6: 4 | BK6: 5 | BL6: 4 | BM6: 4 | BN6: 4 | BO6: 4 | BP6: 5 | BQ6: 5 | BR6: 3 | BS6: 3 | BT6: 3 | BU6: 4 | BV6: 4 | BW6: 3 | BX6: 4 | BY6: 5 | BZ6: 4 | CA6: 4 | CB6: 5 | CC6: 4 | CD6: 5 | CE6: 1 | CF6: 2 | CG6: 2 | CH6: 4 | CI6: 4 | CJ6: 2 | CK6: 2 | CM6: 2 | CN6: 3 | CO6: 4 | CP6: 1 | CQ6: 2 | CS6: 3 | CT6: 2 | CU6: 4 | CV6: 3 | CX6: 1 | CY6: 1 | CZ6: 1 | DB6: 3 | DC6: 12197 | DD6: very easy to understand | DE6: 5be0fb420d5adc0001d6d5b7 | DF6: 1
A7: 45718.455 | B7: 45718.457 | C7: 0 | D7: 74.101.36.175 | E7: 100 | F7: 195 | G7: 1 | H7: 45718.457 | I7: R_3FY1mlyTOLzDbdD | N7: 40.6002 | O7: -74.1469 | P7: anonymous | Q7: EN | R7: 1 | S7: 667c247b3a2743051fdc0f5d | T7: 2 | U7: 1 | W7: 2 | Y7: 4 | Z7: 2 | AA7: 1 | AB7: 2 | AC7: 4 | AD7: 5 | AE7: 1 | AF7: 2 | AG7: 2 | AH7: 1 | AI7: 1 | AJ7: 2 | AK7: 3 | AL7: 2 | AN7: 2 | AO7: 2 | AP7: 5 | AR7: 1 | AS7: 5 | AT7: 4 | AU7: 4 | AV7: 4 | AW7: 4 | AX7: 4 | AY7: 4 | AZ7: 4 | BA7: 3 | BB7: 4 | BC7: 4 | BD7: 3 | BE7: 4 | BF7: 5 | BG7: 4 | BH7: 5 | BI7: 5 | BJ7: 3 | BK7: 2 | BL7: 4 | BM7: 3 | BN7: 4 | BO7: 5 | BP7: 4 | BQ7: 4 | BR7: 5 | BS7: 3 | BT7: 5 | BU7: 4 | BV7: 4 | BW7: 5 | BX7: 4 | BY7: 4 | BZ7: 4 | CA7: 5 | CB7: 5 | CC7: 4 | CD7: 4 | CE7: 1 | CF7: 4 | CG7: 3 | CH7: 4 | CI7: 3 | CJ7: 4 | CK7: 2 | CM7: 1 | CN7: 3 | CO7: 2 | CP7: 4 | CQ7: 1 | CS7: 1 | CT7: 3 | CU7: 1 | CV7: 3 | CX7: 1 | CY7: 1 | CZ7: 2 | DB7: 1 | DC7: 10314 | DE7: 667c247b3a2743051fdc0f5d | DF7: 1
A8: 45718.455 | B8: 45718.458 | C8: 0 | D8: 75.214.77.135 | E8: 100 | F8: 264 | G8: 1 | H8: 45718.458 | I8: R_3MmVu0NevCrAFYo | N8: 40.674 | O8: -73.9701 | P8: anonymous | Q8: EN | R8: 1 | S8: 5e724373a7892a1749fd479d | T8: 2 | U8: 2 | W8: 1 | Y8: 3 | Z8: 2 | AA8: 2 | AB8: 2 | AC8: 2 | AD8: 3 | AE8: 1 | AF8: 2 | AG8: 2 | AH8: 2 | AI8: 2 | AJ8: 1 | AS8: 3 | AT8: 3 | AU8: 3 | AV8: 2 | AW8: 2 | AX8: 2 | AY8: 3 | AZ8: 3 | BA8: 4 | BB8: 3 | BC8: 3 | BD8: 3 | BE8: 3 | BF8: 4 | BG8: 3 | BH8: 3 | BI8: 2 | BJ8: 2 | BK8: 2 | BL8: 2 | BM8: 2 | BN8: 1 | BO8: 4 | BP8: 4 | BQ8: 4 | BR8: 3 | BS8: 3 | BT8: 2 | BU8: 3 | BV8: 3 | BW8: 2 | BX8: 2 | BY8: 3 | BZ8: 2 | CA8: 1 | CB8: 4 | CC8: 3 | CD8: 2 | CE8: 4 | CF8: 3 | CG8: 1 | CL8: 4 | CQ8: 1 | CS8: 2 | CT8: 3 | CU8: 4 | CV8: 2 | CX8: 1 | CY8: 1 | CZ8: 2 | DB8: 5 | DC8: 11216 | DE8: 5e724373a7892a1749fd479d | DF8: 1
A9: 45718.45 | B9: 45718.46 | C9: 0 | D9: 72.45.243.58 | E9: 100 | F9: 930 | G9: 1 | H9: 45718.46 | I9: R_3Veny5RdReBXzr3 | N9: 42.781 | O9: -73.9115 | P9: anonymous | Q9: EN | R9: 1 | S9: 6750718c7d08a1b658702c22 | T9: 2 | U9: 5 | W9: 4 | Y9: 1 | Z9: 2 | AA9: 2 | AB9: 1 | AC9: 1 | AD9: 1 | AE9: 1 | AF9: 2 | AG9: 2 | AH9: 2 | AI9: 2 | AJ9: 1 | AS9: 1 | AT9: 3 | AU9: 1 | AV9: 1 | AW9: 3 | AX9: 5 | AY9: 2 | AZ9: 3 | BA9: 2 | BB9: 4 | BC9: 3 | BD9: 5 | BE9: 3 | BF9: 5 | BG9: 5 | BH9: 2 | BI9: 2 | BJ9: 3 | BK9: 5 | BL9: 3 | BM9: 2 | BN9: 2 | BO9: 2 | BP9: 2 | BQ9: 2 | BR9: 2 | BS9: 3 | BT9: 3 | BU9: 3 | BV9: 2 | BW9: 3 | BX9: 1 | BY9: 4 | BZ9: 4 | CA9: 1 | CB9: 4 | CC9: 4 | CD9: 1 | CE9: 4 | CF9: 3 | CG9: 3 | CQ9: 2 | CS9: 3 | CT9: 5 | CU9: 2 | CV9: 3 | CX9: 1 | CY9: 2 | CZ9: 7 | DB9: 1 | DC9: 12206 | DD9: I dont think every home owner in the world is concerned about having to replace material things | DE9: 6750718c7d08a1b658702c22 | DF9: 1
A10: 45718.451 | B10: 45718.462 | C10: 0 | D10: 172.56.165.131 | E10: 100 | F10: 927 | G10: 1 | H10: 45718.462 | I10: R_3jvL8MBDrZgUtWN | N10: 40.7035 | O10: -73.9235 | P10: anonymous | Q10: EN | R10: 1 | S10: 672c5b912fcc16cf421581e7 | T10: 1 | U10: 1 | W10: 1 | Y10: 1 | Z10: 1 | AA10: 2 | AB10: 1 | AC10: 2 | AD10: 7 | AE10: 4 | AF10: 2 | AG10: 2 | AH10: 1 | AI10: 2 | AJ10: 1 | AS10: 3 | AT10: 4 | AU10: 4 | AV10: 3 | AW10: 3 | AX10: 3 | AY10: 3 | AZ10: 3 | BA10: 3 | BB10: 3 | BC10: 2 | BD10: 2 | BE10: 2 | BF10: 2 | BG10: 2 | BH10: 2 | BI10: 2 | BJ10: 3 | BK10: 4 | BL10: 4 | BM10: 3 | BN10: 4 | BO10: 2 | BP10: 2 | BQ10: 2 | BR10: 2 | BS10: 3 | BT10: 2 | BU10: 3 | BV10: 3 | BW10: 3 | BX10: 3 | BY10: 3 | BZ10: 2 | CA10: 3 | CB10: 3 | CC10: 2 | CD10: 4 | CE10: 4 | CF10: 1 | CG10: 1 | CL10: 3 | CQ10: 2 | CS10: 6 | CT10: 3 | CU10: 5 | CV10: 4 | CX10: 2 | CY10: 2 | CZ10: 8 | DA10: retiree | DB10: 2 | DC10: 08872 | DE10: 672c5b912fcc16cf421581e7 | DF10: 1
A11: 45718.461 | B11: 45718.464 | C11: 0 | D11: 68.198.185.57 | E11: 100 | F11: 249 | G11: 1 | H11: 45718.464 | I11: R_6NywJQEaGDUvvz9 | N11: 40.5828 | O11: -73.9532 | P11: anonymous | Q11: EN | R11: 1 | S11: 66d71dbb91a283b5a18fb170 | T11: 2 | U11: 3 | W11: 1 | Y11: 2 | Z11: 1 | AA11: 1 | AB11: 2 | AC11: 4 | AD11: 6 | AE11: 4 | AF11: 1 | AG11: 2 | AH11: 2 | AI11: 1 | AJ11: 2 | AK11: 1 | AL11: 2 | AN11: 5 | AO11: 2 | AP11: 3 | AR11: 1 | AS11: 5 | AT11: 5 | AU11: 5 | AV11: 5 | AW11: 5 | AX11: 5 | AY11: 5 | AZ11: 5 | BA11: 5 | BB11: 5 | BC11: 5 | BD11: 5 | BE11: 5 | BF11: 5 | BG11: 5 | BH11: 5 | BI11: 5 | BJ11: 2 | BK11: 5 | BL11: 5 | BM11: 3 | BN11: 3 | BO11: 4 | BP11: 3 | BQ11: 5 | BR11: 4 | BS11: 3 | BT11: 4 | BU11: 4 | BV11: 2 | BW11: 2 | BX11: 5 | BY11: 5 | BZ11: 5 | CA11: 5 | CB11: 3 | CC11: 2 | CD11: 4 | CE11: 3 | CF11: 2 | CG11: 4 | CL11: 4 | CQ11: 2 | CS11: 2 | CT11: 3 | CU11: 5 | CV11: 1 | CX11: 1 | CY11: 1 | CZ11: 3 | DB11: 2 | DC11: 11224 | DE11: 66d71dbb91a283b5a18fb170 | DF11: 1
A12: 45718.457 | B12: 45718.465 | C12: 0 | D12: 24.228.254.242 | E12: 100 | F12: 653 | G12: 1 | H12: 45718.465 | I12: R_3XgiyptlALxsBln | N12: 40.4551 | O12: -74.4871 | P12: anonymous | Q12: EN | R12: 1 | S12: 66bf519b34c66d259e5554d1 | T12: 1 | U12: 1 | W12: 1 | Y12: 4 | Z12: 1 | AA12: 1 | AB12: 1 | AC12: 6 | AD12: 2 | AE12: 1 | AF12: 2 | AG12: 1 | AH12: 2 | AI12: 1 | AJ12: 2 | AK12: 2 | AL12: 2 | AN12: 1 | AO12: 2 | AP12: 5 | AR12: 1 | AS12: 4 | AT12: 4 | AU12: 5 | AV12: 4 | AW12: 4 | AX12: 4 | AY12: 4 | AZ12: 4 | BA12: 4 | BB12: 4 | BC12: 4 | BD12: 2 | BE12: 4 | BF12: 4 | BG12: 4 | BH12: 5 | BI12: 4 | BJ12: 3 | BK12: 2 | BL12: 2 | BM12: 4 | BN12: 2 | BO12: 4 | BP12: 4 | BQ12: 4 | BR12: 4 | BS12: 3 | BT12: 2 | BU12: 2 | BV12: 2 | BW12: 4 | BX12: 2 | BY12: 2 | BZ12: 2 | CA12: 2 | CB12: 4 | CC12: 2 | CD12: 2 | CE12: 1 | CF12: 4 | CG12: 1 | CL12: 2 | CQ12: 1 | CS12: 2 | CT12: 3 | CU12: 4 | CV12: 2 | CX12: 1 | CY12: 1 | CZ12: 4 | DB12: 7 | DC12: 07011 | DE12: 66bf519b34c66d259e5554d1 | DF12: 1
A13: 45718.452 | B13: 45718.465 | C13: 0 | D13: 172.56.167.236 | E13: 100 | F13: 1127 | G13: 1 | H13: 45718.465 | I13: R_13ma7vh4uCMKM6d | N13: 40.7035 | O13: -73.9235 | P13: anonymous | Q13: EN | R13: 1 | S13: 66cf6453d66a848ab8d9f3d2 | T13: 2 | U13: 5 | V13: Coop | W13: 2 | Y13: 1 | Z13: 2 | AA13: 2 | AB13: 2 | AC13: 3 | AD13: 2 | AE13: 1 | AF13: 1 | AG13: 2 | AH13: 2 | AI13: 2 | AJ13: 1 | AS13: 4 | AT13: 4 | AU13: 4 | AV13: 4 | AW13: 4 | AX13: 4 | AY13: 4 | AZ13: 4 | BA13: 4 | BB13: 4 | BC13: 3 | BD13: 4 | BE13: 4 | BF13: 3 | BG13: 3 | BH13: 3 | BI13: 3 | BJ13: 3 | BK13: 3 | BL13: 4 | BM13: 4 | BN13: 3 | BO13: 3 | BP13: 3 | BQ13: 3 | BR13: 3 | BS13: 3 | BT13: 2 | BU13: 3 | BV13: 3 | BW13: 3 | BX13: 3 | BY13: 4 | BZ13: 3 | CA13: 3 | CB13: 4 | CC13: 3 | CD13: 3 | CE13: 4 | CF13: 2 | CG13: 1 | CH13: 2 | CI13: 1 | CJ13: 2 | CK13: 3 | CM13: 3 | CN13: 2 | CO13: 4 | CP13: 1 | CQ13: 2 | CS13: 2 | CT13: 2 | CU13: 1 | CV13: 1 | CX13: 1 | CY13: 1 | CZ13: 8 | DA13: Technician | DB13: 3 | DC13: 11220 | DE13: 66cf6453d66a848ab8d9f3d2 | DF13: 1
A14: 45718.462 | B14: 45718.465 | C14: 0 | D14: 151.205.179.101 | E14: 100 | F14: 254 | G14: 1 | H14: 45718.465 | I14: R_3pPvkj1ZuGVGPPX | N14: 40.674 | O14: -73.9701 | P14: anonymous | Q14: EN | R14: 1 | S14: 5e7142237bcd6e05c4128129 | T14: 2 | U14: 2 | W14: 1 | Y14: 1 | Z14: 2 | AA14: 2 | AB14: 2 | AC14: 2 | AD14: 2 | AE14: 1 | AF14: 2 | AG14: 2 | AH14: 2 | AI14: 2 | AJ14: 1 | AS14: 5 | AT14: 4 | AU14: 4 | AV14: 4 | AW14: 2 | AX14: 4 | AY14: 4 | AZ14: 4 | BA14: 5 | BB14: 4 | BC14: 5 | BD14: 3 | BE14: 4 | BF14: 5 | BG14: 3 | BH14: 2 | BI14: 4 | BJ14: 1 | BK14: 2 | BL14: 4 | BM14: 2 | BN14: 1 | BO14: 4 | BP14: 4 | BQ14: 4 | BR14: 2 | BS14: 3 | BT14: 1 | BU14: 4 | BV14: 4 | BW14: 4 | BX14: 2 | BY14: 5 | BZ14: 3 | CA14: 1 | CB14: 4 | CC14: 3 | CD14: 4 | CE14: 4 | CF14: 2 | CG14: 2 | CL14: 4 | CQ14: 1 | CS14: 1 | CT14: 3 | CU14: 1 | CV14: 1 | CX14: 1 | CY14: 1 | CZ14: 2 | DB14: 9 | DC14: 11216 | DE14: 5e7142237bcd6e05c4128129 | DF14: 1
A15: 45718.46 | B15: 45718.465 | C15: 0 | D15: 184.152.224.222 | E15: 100 | F15: 480 | G15: 1 | H15: 45718.465 | I15: R_7cP84dvQgyI2E6d | N15: 40.738 | O15: -73.9858 | P15: anonymous | Q15: EN | R15: 1 | S15: 675793fcd759b993d59985c9 | T15: 2 | U15: 2 | W15: 1 | Y15: 7 | Z15: 2 | AA15: 2 | AB15: 1 | AC15: 2 | AD15: 1 | AE15: 1 | AF15: 2 | AG15: 2 | AH15: 2 | AI15: 2 | AJ15: 1 | AS15: 2 | AT15: 3 | AU15: 4 | AV15: 4 | AW15: 2 | AX15: 4 | AY15: 3 | AZ15: 2 | BA15: 4 | BB15: 3 | BC15: 4 | BD15: 4 | BE15: 3 | BF15: 5 | BG15: 4 | BH15: 1 | BI15: 2 | BJ15: 2 | BK15: 3 | BL15: 2 | BM15: 2 | BN15: 1 | BO15: 1 | BP15: 2 | BQ15: 1 | BR15: 1 | BS15: 3 | BT15: 2 | BU15: 2 | BV15: 4 | BW15: 1 | BX15: 2 | BY15: 4 | BZ15: 3 | CA15: 2 | CB15: 4 | CC15: 4 | CD15: 3 | CE15: 4 | CF15: 3 | CG15: 1 | CL15: 2 | CQ15: 1 | CS15: 1 | CT15: 3 | CU15: 4 | CV15: 2 | CX15: 1 | CY15: 1 | CZ15: 2 | DB15: 4 | DC15: 10009 | DE15: 675793fcd759b993d59985c9 | DF15: 1
A16: 45718.461 | B16: 45718.466 | C16: 0 | D16: 73.193.217.73 | E16: 100 | F16: 389 | G16: 1 | H16: 45718.466 | I16: R_6P2b9DNMuTsK9ON | N16: 40.3162 | O16: -74.5138 | P16: anonymous | Q16: EN | R16: 1 | S16: 67158fc2d3dcb39fb10908dc | T16: 1 | U16: 1 | W16: 4 | X16: Living with family | Y16: 2 | Z16: 2 | AA16: 1 | AB16: 1 | AC16: 5 | AD16: 2 | AE16: 1 | AF16: 2 | AG16: 2 | AH16: 1 | AI16: 1 | AJ16: 2 | AK16: 2 | AL16: 2 | AN16: 2 | AO16: 2 | AP16: 4 | AQ16: Renovations | AR16: 1 | AS16: 3 | AT16: 3 | AU16: 3 | AV16: 3 | AW16: 3 | AX16: 3 | AY16: 1 | AZ16: 3 | BA16: 3 | BB16: 3 | BC16: 3 | BD16: 3 | BE16: 3 | BF16: 1 | BG16: 1 | BH16: 5 | BI16: 5 | BJ16: 5 | BK16: 2 | BL16: 2 | BM16: 5 | BN16: 1 | BO16: 4 | BP16: 5 | BQ16: 5 | BR16: 5 | BS16: 3 | BT16: 3 | BU16: 5 | BV16: 3 | BW16: 3 | BX16: 2 | BY16: 4 | BZ16: 3 | CA16: 2 | CB16: 5 | CC16: 1 | CD16: 1 | CE16: 4 | CF16: 2 | CG16: 1 | CQ16: 2 | CS16: 1 | CT16: 3 | CU16: 1 | CV16: 3 | CX16: 1 | CY16: 1 | CZ16: 2 | DB16: 1 | DC16: 08882 | DD16: You should include questions pertaining to if you live with family and don't own a home yourself but living with family. | DE16: 67158fc2d3dcb39fb10908dc | DF16: 1
A17: 45718.466 | B17: 45718.469 | C17: 0 | D17: 24.89.148.138 | E17: 100 | F17: 257 | G17: 1 | H17: 45718.469 | I17: R_6DU7Ik8ecmUAFlw | N17: 40.6368 | O17: -74.0005 | P17: anonymous | Q17: EN | R17: 1 | S17: 601992d4a11f4e0e0a60ee8a | T17: 2 | U17: 2 | W17: 1 | Y17: 2 | Z17: 2 | AA17: 2 | AB17: 1 | AC17: 2 | AD17: 2 | AE17: 1 | AF17: 2 | AG17: 2 | AH17: 2 | AI17: 2 | AJ17: 1 | AS17: 4 | AT17: 4 | AU17: 4 | AV17: 4 | AW17: 4 | AX17: 4 | AY17: 4 | AZ17: 4 | BA17: 4 | BB17: 4 | BC17: 4 | BD17: 4 | BE17: 4 | BF17: 4 | BG17: 4 | BH17: 2 | BI17: 2 | BJ17: 1 | BK17: 1 | BL17: 1 | BM17: 1 | BN17: 1 | BO17: 1 | BP17: 1 | BQ17: 1 | BR17: 1 | BS17: 3 | BT17: 1 | BU17: 1 | BV17: 3 | BW17: 3 | BX17: 3 | BY17: 3 | BZ17: 3 | CA17: 3 | CB17: 1 | CC17: 1 | CD17: 1 | CE17: 4 | CF17: 3 | CG17: 1 | CL17: 3 | CQ17: 1 | CS17: 2 | CT17: 3 | CU17: 1 | CV17: 1 | CX17: 1 | CY17: 1 | CZ17: 2 | DB17: 9 | DC17: 11221 | DE17: 601992d4a11f4e0e0a60ee8a | DF17: 1
A18: 45718.455 | B18: 45718.469 | C18: 0 | D18: 139.171.134.138 | E18: 100 | F18: 1242 | G18: 1 | H18: 45718.469 | I18: R_3MMOTIVeq9PkM5M | N18: 37.751 | O18: -97.822 | P18: anonymous | Q18: EN | R18: 1 | S18: 6789798be54df25793eaeb00 | T18: 1 | U18: 2 | W18: 1 | Y18: 4 | Z18: 1 | AA18: 1 | AB18: 1 | AC18: 6 | AD18: 3 | AE18: 3 | AF18: 1 | AG18: 1 | AH18: 1 | AI18: 1 | AJ18: 2 | AK18: 2 | AL18: 1 | AN18: 3 | AO18: 1 | AP18: 3 | AR18: 2 | AS18: 3 | AT18: 3 | AU18: 4 | AV18: 3 | AW18: 4 | AX18: 4 | AY18: 4 | AZ18: 4 | BA18: 4 | BB18: 4 | BC18: 4 | BD18: 3 | BE18: 3 | BF18: 3 | BG18: 3 | BH18: 5 | BI18: 4 | BJ18: 4 | BK18: 4 | BL18: 4 | BM18: 4 | BN18: 4 | BO18: 4 | BP18: 4 | BQ18: 4 | BR18: 4 | BS18: 3 | BT18: 4 | BU18: 4 | BV18: 4 | BW18: 3 | BX18: 4 | BY18: 3 | BZ18: 3 | CA18: 3 | CB18: 4 | CC18: 3 | CD18: 3 | CE18: 2 | CF18: 4 | CG18: 2 | CL18: 4 | CQ18: 2 | CS18: 1 | CT18: 3 | CU18: 4 | CV18: 2 | CX18: 1 | CY18: 1 | CZ18: 4 | DB18: 6 | DC18: 44907 | DE18: 6789798be54df25793eaeb00 | DF18: 1
A19: 45718.465 | B19: 45718.469 | C19: 0 | D19: 100.8.77.196 | E19: 100 | F19: 403 | G19: 1 | H19: 45718.469 | I19: R_7g0cInK09cRDHpx | N19: 40.793 | O19: -74.0247 | P19: anonymous | Q19: EN | R19: 1 | S19: 5f84743db0bcc50c63cdb55c | T19: 1 | U19: 1 | W19: 1 | Y19: 1 | Z19: 1 | AA19: 1 | AB19: 1 | AC19: 2 | AD19: 2 | AE19: 1 | AF19: 2 | AG19: 2 | AH19: 2 | AI19: 2 | AJ19: 1 | AS19: 3 | AT19: 2 | AU19: 1 | AV19: 4 | AW19: 3 | AX19: 5 | AY19: 5 | AZ19: 4 | BA19: 2 | BB19: 3 | BC19: 1 | BD19: 2 | BE19: 5 | BF19: 4 | BG19: 4 | BH19: 4 | BI19: 3 | BJ19: 5 | BK19: 1 | BL19: 2 | BM19: 3 | BN19: 2 | BO19: 4 | BP19: 5 | BQ19: 4 | BR19: 5 | BS19: 3 | BT19: 4 | BU19: 4 | BV19: 5 | BW19: 2 | BX19: 3 | BY19: 1 | BZ19: 2 | CA19: 5 | CB19: 3 | CC19: 3 | CD19: 4 | CE19: 3 | CF19: 3 | CG19: 4 | CL19: 5 | CQ19: 2 | CS19: 3 | CT19: 2 | CU19: 3 | CV19: 4 | CX19: 1 | CY19: 1 | CZ19: 6 | DB19: 2 | DC19: 07087 | DE19: 5f84743db0bcc50c63cdb55c | DF19: 1
